Workbook
Name \A: #REF!
Name \A: #REF!
Name \A: #REF!
Name \A: #REF!
Name \A: #REF!
Name \C: #REF!
Name \C: #REF!
Name \C: #REF!
Name \C: #REF!
Name \C: #REF!
Name \D: #REF!
Name \D: #REF!
Name \D: #REF!
Name \D: #REF!
Name \D: #REF!
Name \E: #REF!
Name \E: #REF!
Name \E: #REF!
Name \E: #REF!
Name \E: #REF!
Name \F: #REF!
Name \F: #REF!
Name \F: #REF!
Name \F: #REF!
Name \F: #REF!
Name \G: #REF!
Name \G: #REF!
Name \G: #REF!
Name \G: #REF!
Name \G: #REF!
Name \H: #REF!
Name \H: #REF!
Name \H: #REF!
Name \H: #REF!
Name \H: #REF!
Name \J: #REF!
Name \J: #REF!
Name \J: #REF!
Name \J: #REF!
Name \J: #REF!
Name \M: #REF!
Name \M: #REF!
Name \M: #REF!
Name \M: #REF!
Name \M: #REF!
Name \N: #REF!
Name \N: #REF!
Name \N: #REF!
Name \N: #REF!
Name \N: #REF!
Name \P: #REF!
Name \P: #REF!
Name \P: #REF!
Name \P: #REF!
Name \P: #REF!
Name \Q: #REF!
Name \Q: #REF!
Name \Q: #REF!
Name \Q: #REF!
Name \Q: #REF!

Sheet BP Value Comparision
M1: 1st Draft Comparision | P1: 2nd Draft Comparison
A2: Values (Cr.) | C2: FY 24-25 | E2: FY 25-26 | H2: FY 26-27 | M2: Variance BP 26-27 Vs. BP 25-26 (April) | N2: Variance BP 26-27 Vs. BP 25-26 (Aug) | O2: Variance BP 26-27 Vs. Act 25-26 | P2: Variance BP 26-27 Vs. BP 25-26 (April) | Q2: Variance BP 26-27 Vs. BP 25-26 (Aug) | R2: Variance BP 26-27 Vs. Act 25-26 | T2: BP 25-26 Vs. BP 26-27 (2nd V1 Draft)
C3: BP | D3: Act | E3: BP | F3: BP (Aug) | G3: Act | H3: BP (1st Draft) | I3: BP (2nd Draft) | J3: BP (2nd V1 Draft) | K3: 3rd Draft | L3: Act
A4: Dispatch Value (Yearly) | B4: S.F | C4: 702.13 | D4: 576.9 | E4: 554.7 | F4: 472.22 | G4: 502.7601 | H4: 718.06 | I4: 736 | J4: 706.39967 | K4: 714 | M4: =(H4/E4)-1 -> 0.29450153 | N4: =(H4/F4)-1 -> 0.5206048 | O4: =(H4/G4)-1 -> 0.42823585 | P4: =(I4/E4)-1 -> 0.32684334 | Q4: =(I4/F4)-1 -> 0.55859557 | R4: =(I4/G4)-1 -> 0.46391888 | T4: =J4/E4-1 -> 0.27348057
B5: H.F | C5: 433.49 | D5: 208.78 | E5: 183.9 | F5: 130.12 | G5: 70.24 | H5: 38.05 | I5: 53 | J5: 53.239857 | K5: 53 | M5: =(H5/E5)-1 -> -0.79309407 | N5: =(H5/F5)-1 -> -0.70757762 | O5: =(H5/G5)-1 -> -0.45828588 | P5: =(I5/E5)-1 -> -0.71179989 | Q5: =(I5/F5)-1 -> -0.59268368 | R5: =(I5/G5)-1 -> -0.24544419 | T5: =J5/E5-1 -> -0.71049561
B6: Total | C6: =SUM(C4:C5) -> 1135.62 | D6: =SUM(D4:D5) -> 785.68 | E6: =SUM(E4:E5) -> 738.6 | F6: =SUM(F4:F5) -> 602.34 | G6: =SUM(G4:G5) -> 573.0001 | H6: =SUM(H4:H5) -> 756.11 | I6: =SUM(I4:I5) -> 789 | J6: =SUM(J4:J5) -> 759.63953 | K6: =SUM(K4:K5) -> 767 | M6: =(H6/E6)-1 -> 0.023707013 | N6: =(H6/F6)-1 -> 0.25528771 | O6: =(H6/G6)-1 -> 0.31956347 | P6: =(I6/E6)-1 -> 0.068237206 | Q6: =(I6/F6)-1 -> 0.30989142 | R6: =(I6/G6)-1 -> 0.37696311 | T6: =J6/E6-1 -> 0.028485688
A8: Dispatch Value (Monthly) | B8: S.F | C8: =C4/12 -> 58.510833 | D8: =D4/12 -> 48.075 | E8: =E4/12 -> 46.225 | F8: =F4/12 -> 39.351667 | G8: =G4/12 -> 41.896675 | H8: =H4/12 -> 59.838333 | I8: =I4/12 -> 61.333333 | J8: =J4/12 -> 58.866639 | K8: =K4/12 -> 59.5 | M8: =(H8/E8)-1 -> 0.29450153 | N8: =(H8/F8)-1 -> 0.5206048 | O8: =(H8/G8)-1 -> 0.42823585 | P8: =(I8/E8)-1 -> 0.32684334 | Q8: =(I8/F8)-1 -> 0.55859557 | R8: =(I8/G8)-1 -> 0.46391888 | T8: =J8/E8-1 -> 0.27348057
B9: H.F | C9: =C5/12 -> 36.124167 | D9: =D5/12 -> 17.398333 | E9: =E5/12 -> 15.325 | F9: =F5/12 -> 10.843333 | G9: =G5/12 -> 5.8533333 | H9: =H5/12 -> 3.1708333 | I9: =I5/12 -> 4.4166667 | J9: =J5/12 -> 4.4366548 | K9: =K5/12 -> 4.4166667 | M9: =(H9/E9)-1 -> -0.79309407 | N9: =(H9/F9)-1 -> -0.70757762 | O9: =(H9/G9)-1 -> -0.45828588 | P9: =(I9/E9)-1 -> -0.71179989 | Q9: =(I9/F9)-1 -> -0.59268368 | R9: =(I9/G9)-1 -> -0.24544419 | T9: =J9/E9-1 -> -0.71049561
B10: Total | C10: =SUM(C8:C9) -> 94.635 | D10: =SUM(D8:D9) -> 65.473333 | E10: =SUM(E8:E9) -> 61.55 | F10: =SUM(F8:F9) -> 50.195 | G10: =SUM(G8:G9) -> 47.750008 | H10: =SUM(H8:H9) -> 63.009167 | I10: =SUM(I8:I9) -> 65.75 | J10: =SUM(J8:J9) -> 63.303294 | K10: =SUM(K8:K9) -> 63.916667 | M10: =(H10/E10)-1 -> 0.023707013 | N10: =(H10/F10)-1 -> 0.25528771 | O10: =(H10/G10)-1 -> 0.31956347 | P10: =(I10/E10)-1 -> 0.068237206 | Q10: =(I10/F10)-1 -> 0.30989142 | R10: =(I10/G10)-1 -> 0.37696311 | T10: =J10/E10-1 -> 0.028485688
A12: Avg Daily Deployment | B12: S.F. | C12: 1773 | D12: 1660 | E12: 1589.6667 | G12: 1561 | H12: 1607 | I12: 1642.2083 | J12: 1593.875 | T12: =J12/E12-1 -> 0.0026473055
B13: H.F. | C13: 529 | D13: 373 | E13: 245 | G13: 178 | H13: 66 | I13: 66 | J13: 66 | T13: =J13/E13-1 -> -0.73061224
B14: Total | C14: =SUM(C12:C13) -> 2302 | D14: =SUM(D12:D13) -> 2033 | E14: =SUM(E12:E13) -> 1834.6667 | G14: =SUM(G12:G13) -> 1739 | H14: =SUM(H12:H13) -> 1673 | I14: =SUM(I12:I13) -> 1708.2083 | J14: =SUM(J12:J13) -> 1659.875 | T14: =J14/E14-1 -> -0.095271621
A18: Values (Cr.) | C18: BP (1st Draft) | D18: BP (2nd Draft) | E18: BP (2nd V1 Draft)
A20: Dispatch Value (Yearly) | B20: S.F | C20: 718.06 | D20: 736 | E20: 706.39967
B21: H.F | C21: 38.05 | D21: 53 | E21: 53.239857
B22: Total | C22: =SUM(C20:C21) -> 756.11 | D22: =SUM(D20:D21) -> 789 | E22: =SUM(E20:E21) -> 759.63953
A24: Dispatch Value (Monthly) | B24: S.F | C24: =C20/12 -> 59.838333 | D24: =D20/12 -> 61.333333 | E24: =E20/12 -> 58.866639
B25: H.F | C25: =C21/12 -> 3.1708333 | D25: =D21/12 -> 4.4166667 | E25: =E21/12 -> 4.4366548
B26: Total | C26: =SUM(C24:C25) -> 63.009167 | D26: =SUM(D24:D25) -> 65.75 | E26: =SUM(E24:E25) -> 63.303294
A29: Avg Daily Deployment | B29: HC | C29: BP (1st Draft) | D29: BP (2nd Draft) | E29: BP (2nd V1 Draft)
B31: S.F. | C31: 1609 | D31: 1642.2083 | E31: 1593.875
B32: H.F. | C32: 66 | D32: 66 | E32: 66
A33: Total | C33: =SUM(C31:C32) -> 1675 | D33: =SUM(D31:D32) -> 1708.2083 | E33: =SUM(E31:E32) -> 1659.875
A35: Production Planning (Yearly Avg.) | B35: Tufting (SQM) | C35: 1293651.6 | D35: 1425035.1 | E35: 1332969.6
B36: CT | C36: =C40 -> 188021.93 | D36: =D40 -> 180072.81 | E36: =E40 -> 180072.81
B37: W2W | C37: =C41 -> 185651.88 | D37: =D41 -> 186607.73 | E37: =E41 -> 186160.71
B38: AR | C38: =C42+C43 -> 919977.82 | D38: =D42+D43 -> 1058354.5 | E38: =E42+E43 -> 966736.09
B39: Inhouse (AR+W2W+CT) | C39: =SUM(C40:C42) -> 648616.84 | D39: =SUM(D40:D42) -> 620856.68 | E39: =SUM(E40:E42) -> 619313.42
B40: CT | C40: 188021.93 | D40: 180072.81 | E40: 180072.81
B41: W2W | C41: 185651.88 | D41: 186607.73 | E41: 186160.71
B42: AR | C42: 274943.03 | D42: 254176.14 | E42: 253079.89
B43: Vapi | C43: =C35-C39 -> 645034.79 | D43: =D35-D39 -> 804178.41 | E43: =E35-E39 -> 713656.19
C46: =C35/30.5/C31 -> 26.360974 | D46: =D35/30.5/D31 -> 28.450995 | E46: =E35/30.5/E31 -> 27.419918
T48: Values (Cr.) | V48: FY 26-27
V49: BP (1st Draft) | W49: BP (2nd Draft) | X49: BP (2nd V1 Draft) | Y49: HC 1st Draft | Z49: HC 2nd Draft | AA49: HC 2nd V1 Draft
T50: Dispatch Value (Yearly) | U50: S.F | V50: 718 | W50: 736 | X50: 706.39967 | Y50: 1,609 | Z50: 1,642 | AA50: 1593.875
U51: H.F | V51: 38 | W51: 53 | X51: 53.239857 | Y51: 66 | Z51: 66 | AA51: 66
U52: Total | V52: 756 | W52: 789 | X52: 759.63953 | Y52: 1,675 | Z52: 1,708 | AA52: =SUM(AA50:AA51) -> 1659.875

Sheet Comparison BP 25-26 Vs 26-27 
A1: Plant | B1: BP 2025-26 | O1: BP 2026-27 (2nd V1 Draft)
B2: Avg/Day | M2: =ROUNDUP(G2*J2,0)*+M2:M39I2 -> #NAME? | O2: Avg/Day
B3: Section | C3: Capacity | D3: UoM | E3: Prod/Day | F3: HC/Day | G3: Remarks | H3: Associate | I3: NAPs | J3: CLM - MD | K3: CLM - PR | L3: Total | O3: ='Workmen Category'!A2 -> Section | P3: ='Workmen Category'!BW2 -> Avg Prodn | Q3: ='Workmen Category'!BX2 -> Avg | R3: ='Workmen Category'!BY2 -> Associate | S3: ='Workmen Category'!BZ2 -> NAPs | T3: ='Workmen Category'!CA2 -> CLM - MD | U3: ='Workmen Category'!CB2 -> CLM - PR | V3: ='Workmen Category'!CC2 -> Total | W3: ='Workmen Category'!CD2 -> Remarks | X3: Note
A4: S.F. | B4: 1. POY | C4: ='Monthly HC & Prodn Working'!C3 -> 32121.952 | D4: Kg | E4: 26855.666 | F4: 41 | G4: All | H4: 35 | I4: 3.1666667 | J4: 2.8333333 | L4: =SUM(H4:K4) -> 41 | O4: ='Workmen Category'!A3 -> 1. POY | P4: ='Workmen Category'!BW3 -> 37828.86 | Q4: ='Workmen Category'!BX3 -> 43 | R4: ='Workmen Category'!BY3 -> 35 | S4: ='Workmen Category'!BZ3 -> 5 | T4: ='Workmen Category'!CA3 -> 3 | U4: ='Workmen Category'!CB3 | V4: ='Workmen Category'!CC3 -> 43 | W4: ='Workmen Category'!CD3 -> All
A5: S.F. | B5: 2. BCF | C5: ='Monthly HC & Prodn Working'!C4 -> 21686.572 | D5: Kg | E5: 11436.447 | F5: 34.333333 | G5: 10 Winder | H5: 26 | I5: 5.3333333 | J5: 3 | L5: =SUM(H5:K5) -> 34.333333 | O5: ='Workmen Category'!A4 -> 2. BCF | P5: ='Workmen Category'!BW4 -> 11641.995 | Q5: ='Workmen Category'!BX4 -> 28.166667 | R5: ='Workmen Category'!BY4 -> 20.666667 | S5: ='Workmen Category'!BZ4 -> 4.5 | T5: ='Workmen Category'!CA4 -> 3 | U5: ='Workmen Category'!CB4 | V5: ='Workmen Category'!CC4 -> 28.166667 | W5: ='Workmen Category'!CD4 -> 11 Winder | X5: Winder Operator Utilized from POY. Multitasking
A6: S.F. | B6: 3. Texturizing | C6: ='Monthly HC & Prodn Working'!C5 -> 29388.133 | D6: Kg | E6: 26560.254 | F6: 83.333333 | G6: All | H6: 49 | I6: 24 | J6: 9 | L6: =SUM(H6:K6) -> 82 | O6: ='Workmen Category'!A5 -> 3. Texturizing | P6: ='Workmen Category'!BW5 -> 37771.136 | Q6: ='Workmen Category'!BX5 -> 84 | R6: ='Workmen Category'!BY5 | S6: ='Workmen Category'!BZ5 | T6: ='Workmen Category'!CA5 | U6: ='Workmen Category'!CB5 -> 84 | V6: ='Workmen Category'!CC5 -> 84 | W6: ='Workmen Category'!CD5 -> All | X6: 49 Associate, 24 NAPs & 9 CLM-MD Converted to CLM-PR
A7: S.F. | B7: 4. Parallel Winding | C7: ='Monthly HC & Prodn Working'!C6 -> 14098.76 | D7: Kg | E7: 14168.365 | F7: 27 | G7: All | H7: 6 | I7: 21 | L7: =SUM(H7:K7) -> 27 | O7: ='Workmen Category'!A6 -> 4. Parallel Winding | P7: ='Workmen Category'!BW6 -> 21152.914 | Q7: ='Workmen Category'!BX6 -> 27 | R7: ='Workmen Category'!BY6 | S7: ='Workmen Category'!BZ6 | T7: ='Workmen Category'!CA6 | U7: ='Workmen Category'!CB6 -> 27 | V7: ='Workmen Category'!CC6 -> 27 | W7: ='Workmen Category'!CD6 -> All | X7: 6 Associate, 21 CLM-MD Converted to CLM-PR
A8: S.F. | B8: Rewinding | C8: ='Monthly HC & Prodn Working'!C7 -> 0 | D8: Kg | F8: 14 | H8: 2 | I8: 0 | J8: 12 | L8: =SUM(H8:K8) -> 14 | O8: ='Workmen Category'!A7 -> Rewinding | P8: ='Workmen Category'!BW7 -> 0 | Q8: ='Workmen Category'!BX7 -> 15 | R8: ='Workmen Category'!BY7 -> 2 | S8: ='Workmen Category'!BZ7 | T8: ='Workmen Category'!CA7 -> 13 | U8: ='Workmen Category'!CB7 | V8: ='Workmen Category'!CC7 -> 15 | W8: ='Workmen Category'!CD7 -> 0
A9: S.F. | B9: 5. Multiply | C9: ='Monthly HC & Prodn Working'!C8 -> 11869.222 | D9: Kg | E9: 3925.8343 | F9: 104 | K9: 104 | L9: =SUM(H9:K9) -> 104 | O9: ='Workmen Category'!A8 -> 5. Multiply | P9: ='Workmen Category'!BW8 -> 4829.4533 | Q9: ='Workmen Category'!BX8 -> 124.16667 | R9: ='Workmen Category'!BY8 | S9: ='Workmen Category'!BZ8 | T9: ='Workmen Category'!CA8 | U9: ='Workmen Category'!CB8 -> 124.16667 | V9: ='Workmen Category'!CC8 -> 124.16667 | W9: ='Workmen Category'!CD8 -> 0
A10: S.F. | B10: TFO | C10: ='Monthly HC & Prodn Working'!C9 -> 0 | D10: Kg | E10: 5598.9241 | L10: =SUM(H10:K10) -> 0 | O10: ='Workmen Category'!A9 -> TFO | P10: ='Workmen Category'!BW9 -> 7407.3248 | Q10: ='Workmen Category'!BX9 -> 0 | R10: ='Workmen Category'!BY9 | S10: ='Workmen Category'!BZ9 | T10: ='Workmen Category'!CA9 | U10: ='Workmen Category'!CB9 | V10: ='Workmen Category'!CC9 -> 0 | W10: ='Workmen Category'!CD9 -> 0
A11: S.F. | B11: Auto Clave | C11: ='Monthly HC & Prodn Working'!C10 -> 0 | D11: Kg | E11: 1838.4291 | L11: =SUM(H11:K11) -> 0 | O11: ='Workmen Category'!A10 -> Auto Clave | P11: ='Workmen Category'!BW10 -> 2577.8715 | Q11: ='Workmen Category'!BX10 -> 0 | R11: ='Workmen Category'!BY10 | S11: ='Workmen Category'!BZ10 | T11: ='Workmen Category'!CA10 | U11: ='Workmen Category'!CB10 | V11: ='Workmen Category'!CC10 -> 0 | W11: ='Workmen Category'!CD10 -> 0
A12: S.F. | B12: 6. Cabling | C12: ='Monthly HC & Prodn Working'!C11 -> 39644.343 | D12: Kg | E12: 29084.556 | F12: 63.75 | G12: 18 M/C | H12: 34 | I12: 26.75 | J12: 3 | L12: =SUM(H12:K12) -> 63.75 | O12: ='Workmen Category'!A11 -> 6. Cabling | P12: ='Workmen Category'!BW11 -> 36103.398 | Q12: ='Workmen Category'!BX11 -> 64.166667 | R12: ='Workmen Category'!BY11 | S12: ='Workmen Category'!BZ11 | T12: ='Workmen Category'!CA11 | U12: ='Workmen Category'!CB11 -> 64.166667 | V12: ='Workmen Category'!CC11 -> 64.166667 | W12: ='Workmen Category'!CD11 -> 18 M/C | X12: 34 Associate, 27 NAPs, 3 CLM MD Converted to CLM-PR
A13: S.F. | B13: 7. Heat Set | C13: ='Monthly HC & Prodn Working'!C12 -> 22591.213 | D13: Kg | E13: 31488.175 | F13: 80.333333 | G13: 6 M/C | H13: 40 | I13: 39 | J13: 0.33333333 | L13: =SUM(H13:K13) -> 79.333333 | O13: ='Workmen Category'!A12 -> 7. Heat Set | P13: ='Workmen Category'!BW12 -> 33603.811 | Q13: ='Workmen Category'!BX12 -> 59.916667 | R13: ='Workmen Category'!BY12 -> 42 | S13: ='Workmen Category'!BZ12 -> 30.166667 | T13: ='Workmen Category'!CA12 -> 6.6666667 | U13: ='Workmen Category'!CB12 | V13: ='Workmen Category'!CC12 -> 78.833333 | W13: ='Workmen Category'!CD12 -> 5 M/C
A14: S.F. | B14: Yarn Common | C14: ='Monthly HC & Prodn Working'!C13 -> 0 | F14: 24 | H14: 1 | I14: 0 | J14: 6 | K14: 17 | L14: =SUM(H14:K14) -> 24 | O14: ='Workmen Category'!A13 -> Yarn Common | P14: ='Workmen Category'!BW13 -> 0 | Q14: ='Workmen Category'!BX13 -> 24 | R14: ='Workmen Category'!BY13 | S14: ='Workmen Category'!BZ13 | T14: ='Workmen Category'!CA13 -> 6 | U14: ='Workmen Category'!CB13 -> 18 | V14: ='Workmen Category'!CC13 -> 24 | W14: ='Workmen Category'!CD13 -> 0
A15: S.F. | B15: Master Batch | C15: ='Monthly HC & Prodn Working'!C14 -> 0 | D15: Kg | E15: 1124.3683 | F15: 30 | H15: 20.5 | I15: 9.5 | L15: =SUM(H15:K15) -> 30 | O15: ='Workmen Category'!A14 -> Master Batch | P15: ='Workmen Category'!BW14 -> 0 | Q15: ='Workmen Category'!BX14 -> 31 | R15: ='Workmen Category'!BY14 -> 20 | S15: ='Workmen Category'!BZ14 -> 11 | T15: ='Workmen Category'!CA14 | U15: ='Workmen Category'!CB14 | V15: ='Workmen Category'!CC14 -> 31 | W15: ='Workmen Category'!CD14 -> 0
A16: S.F. | B16: 8. Tufting | C16: ='Monthly HC & Prodn Working'!C15 -> 63821.5 | D16: SQM | E16: 39197.819 | F16: 171.25 | G16: 15 M/C | H16: 58 | I16: 64.666667 | J16: 36.833333 | K16: 12 | L16: =SUM(H16:K16) -> 171.5 | O16: ='Workmen Category'!A15 -> 8. Tufting | P16: ='Workmen Category'!BW15 -> 46120.959 | Q16: ='Workmen Category'!BX15 -> 165 | R16: ='Workmen Category'!BY15 -> 60 | S16: ='Workmen Category'!BZ15 -> 66 | T16: ='Workmen Category'!CA15 -> 27 | U16: ='Workmen Category'!CB15 -> 12 | V16: ='Workmen Category'!CC15 -> 165 | W16: ='Workmen Category'!CD15 -> 13 M/C | X16: Prodution on High Output M/C increases
A17: S.F. | B17: 9.1 Printing - Chromojet | C17: ='Monthly HC & Prodn Working'!C16 -> 3314.4422 | D17: SQM | E17: 3507.6153 | F17: 38 | G17: 2.33 Shift | H17: 19 | I17: 19 | L17: =SUM(H17:K17) -> 38 | O17: ='Workmen Category'!A16 -> 9.1 Printing - Chromojet | P17: ='Workmen Category'!BW16 -> 4691.4354 | Q17: ='Workmen Category'!BX16 -> 48.5 | R17: ='Workmen Category'!BY16 -> 30.166667 | S17: ='Workmen Category'!BZ16 -> 15.333333 | T17: ='Workmen Category'!CA16 -> 3 | U17: ='Workmen Category'!CB16 | V17: ='Workmen Category'!CC16 -> 48.5 | W17: ='Workmen Category'!CD16 -> 3 Shift
A18: S.F. | B18: 9.2 Printing - Digital | C18: ='Monthly HC & Prodn Working'!C17 -> 2480.0256 | D18: SQM | E18: 910.8 | G18: 1 Shift | L18: =SUM(H18:K18) -> 0 | O18: ='Workmen Category'!A17 -> 9.2 Printing - Digital | P18: ='Workmen Category'!BW17 -> 1415.1439 | Q18: ='Workmen Category'!BX17 -> 0 | R18: ='Workmen Category'!BY17 | S18: ='Workmen Category'!BZ17 | T18: ='Workmen Category'!CA17 | U18: ='Workmen Category'!CB17 | V18: ='Workmen Category'!CC17 -> 0 | W18: ='Workmen Category'!CD17 -> 2.36 Shift
A19: S.F. | B19: 10.1 Carpet Tiles | C19: ='Monthly HC & Prodn Working'!C18 -> 14758.225 | D19: SQM | E19: 4744.4612 | F19: 91.5 | G19: 1 Shift | H19: 52 | I19: 26 | J19: 13.5 | L19: =SUM(H19:K19) -> 91.5 | O19: ='Workmen Category'!A18 -> 10.1 Carpet Tiles | P19: ='Workmen Category'!BW18 -> 5002.3714 | Q19: ='Workmen Category'!BX18 -> 108.5 | R19: ='Workmen Category'!BY18 -> 58.833333 | S19: ='Workmen Category'!BZ18 -> 32.5 | T19: ='Workmen Category'!CA18 -> 16.333333 | U19: ='Workmen Category'!CB18 | V19: ='Workmen Category'!CC18 -> 107.66667 | W19: ='Workmen Category'!CD18 -> 1.75 Shift | X19: Consider 6 HC for TPR Line
A20: S.F. | B20: 10.2 W2W | C20: ='Monthly HC & Prodn Working'!C19 -> 19608.37 | D20: SQM | E20: 13754.529 | G20: 2 Shift | L20: =SUM(H20:K20) -> 0 | O20: ='Workmen Category'!A19 -> 10.2 W2W | P20: ='Workmen Category'!BW19 -> 18816.099 | Q20: ='Workmen Category'!BX19 -> 0 | R20: ='Workmen Category'!BY19 | S20: ='Workmen Category'!BZ19 | T20: ='Workmen Category'!CA19 | U20: ='Workmen Category'!CB19 | V20: ='Workmen Category'!CC19 -> 0 | W20: ='Workmen Category'!CD19 -> 2.72 Shift
A21: S.F. | B21: CSP | C21: ='Monthly HC & Prodn Working'!C20 -> 11666.667 | D21: SQM | E21: 7360.7232 | F21: 244.16667 | H21: 33 | I21: 35.416667 | J21: 45.75 | K21: 130 | L21: =SUM(H21:K21) -> 244.16667 | O21: ='Workmen Category'!A20 -> CSP | P21: ='Workmen Category'!BW20 -> 9900.8122 | Q21: ='Workmen Category'!BX20 -> 265.70833 | R21: ='Workmen Category'!BY20 -> 42 | S21: ='Workmen Category'!BZ20 -> 34 | T21: ='Workmen Category'!CA20 -> 0 | U21: ='Workmen Category'!CB20 -> 189.70833 | V21: ='Workmen Category'!CC20 -> 265.70833 | W21: ='Workmen Category'!CD20 -> 0
A22: S.F. | B22: Process Control | F22: 12 | I22: 12 | L22: =SUM(H22:K22) -> 12 | O22: ='Workmen Category'!A21 -> Process Control | P22: ='Workmen Category'!BW21 -> 0 | Q22: ='Workmen Category'!BX21 -> 12 | R22: ='Workmen Category'!BY21 -> 8 | S22: ='Workmen Category'!BZ21 -> 4 | T22: ='Workmen Category'!CA21 | U22: ='Workmen Category'!CB21 | V22: ='Workmen Category'!CC21 -> 12 | W22: ='Workmen Category'!CD21 -> 0
A23: S.F. | B23: TQM | F23: 84 | H23: 45 | I23: 39 | J23: 0 | K23: 0 | L23: =SUM(H23:K23) -> 84 | O23: ='Workmen Category'!A22 -> TQM | P23: ='Workmen Category'!BW22 -> 0 | Q23: ='Workmen Category'!BX22 -> 93 | R23: ='Workmen Category'!BY22 -> 53 | S23: ='Workmen Category'!BZ22 -> 40 | T23: ='Workmen Category'!CA22 | U23: ='Workmen Category'!CB22 | V23: ='Workmen Category'!CC22 -> 93 | W23: ='Workmen Category'!CD22 -> 0 | X23: Added 3 TQM for 1 Packing Line, 3 For Printing and 3 For CT
A24: S.F. | B24: Engg. | F24: 50 | H24: 48 | I24: 2 | J24: 0 | K24: 0 | L24: =SUM(H24:K24) -> 50 | O24: ='Workmen Category'!A23 -> Engg. | P24: ='Workmen Category'!BW23 -> 0 | Q24: ='Workmen Category'!BX23 -> 50 | R24: ='Workmen Category'!BY23 -> 40 | S24: ='Workmen Category'!BZ23 -> 5 | T24: ='Workmen Category'!CA23 -> 5 | U24: ='Workmen Category'!CB23 | V24: ='Workmen Category'!CC23 -> 50 | W24: ='Workmen Category'!CD23 -> 0
A25: S.F. | B25: Engg. | F25: 63 | H25: 31 | I25: 2 | J25: 30 | L25: =SUM(H25:K25) -> 63 | O25: ='Workmen Category'!A24 -> Engg. | P25: ='Workmen Category'!BW24 -> 0 | Q25: ='Workmen Category'!BX24 -> 63 | R25: ='Workmen Category'!BY24 -> 32 | S25: ='Workmen Category'!BZ24 -> 8 | T25: ='Workmen Category'!CA24 -> 11 | U25: ='Workmen Category'!CB24 -> 12 | V25: ='Workmen Category'!CC24 -> 63 | W25: ='Workmen Category'!CD24 -> 0
A26: S.F. | B26: R&D (PD) | F26: 33 | H26: 21 | I26: 5 | J26: 7 | L26: =SUM(H26:K26) -> 33 | O26: ='Workmen Category'!A25 -> R&D (PD) | P26: ='Workmen Category'!BW25 -> 0 | Q26: ='Workmen Category'!BX25 -> 38 | R26: ='Workmen Category'!BY25 -> 22 | S26: ='Workmen Category'!BZ25 -> 9 | T26: ='Workmen Category'!CA25 -> 7 | U26: ='Workmen Category'!CB25 | V26: ='Workmen Category'!CC25 -> 38 | W26: ='Workmen Category'!CD25 -> 0 | X26: 1 HC in Yarn, 1 in Tufting and 3 in M-Tuft
A27: S.F. | B27: SCM (Stores & WH) | F27: 72 | H27: 29 | I27: 5 | J27: 38 | L27: =SUM(H27:K27) -> 72 | O27: ='Workmen Category'!A26 -> SCM (Stores & WH) | P27: ='Workmen Category'!BW26 -> 0 | Q27: ='Workmen Category'!BX26 -> 70 | R27: ='Workmen Category'!BY26 -> 28 | S27: ='Workmen Category'!BZ26 -> 5 | T27: ='Workmen Category'!CA26 -> 37 | U27: ='Workmen Category'!CB26 | V27: ='Workmen Category'!CC26 -> 70 | W27: ='Workmen Category'!CD26 -> 0
A28: S.F. | B28: SCM (Stores & WH) | F28: 30 | H28: 2 | I28: 0 | J28: 2 | K28: 26 | L28: =SUM(H28:K28) -> 30 | O28: ='Workmen Category'!A27 -> SCM (Stores & WH) | P28: ='Workmen Category'!BW27 -> 0 | Q28: ='Workmen Category'!BX27 -> 30 | R28: ='Workmen Category'!BY27 -> 2 | S28: ='Workmen Category'!BZ27 | T28: ='Workmen Category'!CA27 -> 2 | U28: ='Workmen Category'!CB27 -> 26 | V28: ='Workmen Category'!CC27 -> 30 | W28: ='Workmen Category'!CD27 -> 0
A29: S.F. | B29: Common | F29: 199 | H29: 28 | I29: 7 | J29: 165 | L29: =SUM(H29:K29) -> 200 | O29: ='Workmen Category'!A28 -> Common | P29: ='Workmen Category'!BW28 -> 0 | Q29: ='Workmen Category'!BX28 -> 175 | R29: ='Workmen Category'!BY28 -> 30 | S29: ='Workmen Category'!BZ28 -> 5 | T29: ='Workmen Category'!CA28 -> 140 | U29: ='Workmen Category'!CB28 | V29: ='Workmen Category'!CC28 -> 175 | W29: ='Workmen Category'!CD28 -> 0 | X29: 2 Reduce in PPC, and 14 in Common Admin
O30: ='Workmen Category'!A29 -> 0
A31: S.F. | B31: Total | F31: =SUM(F4:F29) -> 1589.6667 | H31: =SUM(H4:H29) -> 579.5 | I31: =SUM(I4:I29) -> 345.83333 | J31: =SUM(J4:J29) -> 374.25 | K31: =SUM(K4:K29) -> 289 | L31: =SUM(L4:L29) -> 1588.5833 | Q31: =SUM(Q4:Q29) -> 1619.125 | R31: =SUM(R4:R29) -> 525.66667 | S31: =SUM(S4:S29) -> 274.5 | T31: =SUM(T4:T29) -> 280 | U31: =SUM(U4:U29) -> 557.04167 | V31: =SUM(V4:V29) -> 1637.2083
A36: H.F. | B36: TQM | F36: 34 | H36: 23 | I36: 11 | J36: 0 | K36: 0 | L36: =SUM(H36:K36) -> 34 | O36: ='Workmen Category'!A32 -> TQM | P36: ='Workmen Category'!BW32 -> 0 | Q36: ='Workmen Category'!BX32 -> 4 | R36: ='Workmen Category'!BY32 -> 4 | S36: ='Workmen Category'!BZ32 | T36: ='Workmen Category'!CA32 | U36: ='Workmen Category'!CB32 | V36: ='Workmen Category'!CC32 -> 4 | W36: ='Workmen Category'!CD32 -> 0
A37: H.F. | B37: Engg. | F37: 20 | H37: 20 | I37: 0 | J37: 0 | K37: 0 | L37: =SUM(H37:K37) -> 20 | O37: ='Workmen Category'!A33 -> Engg. | P37: ='Workmen Category'!BW33 -> 0 | Q37: ='Workmen Category'!BX33 -> 4 | R37: ='Workmen Category'!BY33 -> 4 | S37: ='Workmen Category'!BZ33 | T37: ='Workmen Category'!CA33 | U37: ='Workmen Category'!CB33 | V37: ='Workmen Category'!CC33 -> 4 | W37: ='Workmen Category'!CD33 -> 0
A38: H.F. | B38: R&D (PD) | F38: 6 | H38: 5.97 | I38: 0 | J38: 0 | K38: 0 | L38: =SUM(H38:K38) -> 5.97 | O38: ='Workmen Category'!A34 -> R&D (PD) | P38: ='Workmen Category'!BW34 -> 0 | Q38: ='Workmen Category'!BX34 -> 0 | R38: ='Workmen Category'!BY34 | S38: ='Workmen Category'!BZ34 | T38: ='Workmen Category'!CA34 | U38: ='Workmen Category'!CB34 | V38: ='Workmen Category'!CC34 -> 0 | W38: ='Workmen Category'!CD34 -> 0
A39: H.F. | L39: =SUM(H39:K39) -> 0 | O39: ='Workmen Category'!A35 -> Common | P39: ='Workmen Category'!BW35 -> 0 | Q39: ='Workmen Category'!BX35 -> 8 | R39: ='Workmen Category'!BY35 | S39: ='Workmen Category'!BZ35 | T39: ='Workmen Category'!CA35 -> 8 | U39: ='Workmen Category'!CB35 | V39: ='Workmen Category'!CC35 -> 8 | W39: ='Workmen Category'!CD35 -> 0
A40: H.F. | B40: SCM (Stores & WH) | F40: 20 | H40: 8.4098361 | I40: 1 | J40: 10.557377 | L40: =SUM(H40:K40) -> 19.967213 | O40: ='Workmen Category'!A36 -> SCM (Stores & WH) | P40: ='Workmen Category'!BW36 -> 0 | Q40: ='Workmen Category'!BX36 -> 4 | R40: ='Workmen Category'!BY36 -> 4 | S40: ='Workmen Category'!BZ36 | T40: ='Workmen Category'!CA36 | U40: ='Workmen Category'!CB36 | V40: ='Workmen Category'!CC36 -> 4 | W40: ='Workmen Category'!CD36 -> 0
A41: H.F. | B41: SPC | E41: 8131.8648 | F41: 165 | H41: 65.557377 | I41: 35 | J41: 50 | K41: 14 | L41: =SUM(H41:K41) -> 164.55738 | O41: ='Workmen Category'!A37 -> SPC | P41: ='Workmen Category'!BW37 -> 0 | Q41: ='Workmen Category'!BX37 -> 46 | R41: ='Workmen Category'!BY37 -> 20 | S41: ='Workmen Category'!BZ37 | T41: ='Workmen Category'!CA37 -> 12 | U41: ='Workmen Category'!CB37 -> 14 | V41: ='Workmen Category'!CC37 -> 46 | W41: ='Workmen Category'!CD37 -> 0
A42: H.F. | B42: Total | F42: =SUM(F36:F41) -> 245 | H42: =SUM(H36:H41) -> 122.93721 | I42: =SUM(I36:I41) -> 47 | J42: =SUM(J36:J41) -> 60.557377 | K42: =SUM(K36:K41) -> 14 | L42: =SUM(L36:L41) -> 244.49459 | P42: ='Workmen Category'!BW38 -> 0 | Q42: =SUM(Q36:Q41) -> 66 | R42: ='Workmen Category'!BY38 -> 32 | S42: ='Workmen Category'!BZ38 -> 0 | T42: ='Workmen Category'!CA38 -> 20 | U42: ='Workmen Category'!CB38 -> 14 | V42: ='Workmen Category'!CC38 -> 66 | W42: ='Workmen Category'!CD38 -> 0
P43: ='Workmen Category'!BW39 -> 0 | Q43: ='Workmen Category'!BX39 -> 0 | R43: ='Workmen Category'!BY39 -> 0 | S43: ='Workmen Category'!BZ39 -> 0 | T43: ='Workmen Category'!CA39 -> 0 | U43: ='Workmen Category'!CB39 -> 0 | V43: ='Workmen Category'!CC39 -> 0 | W43: ='Workmen Category'!CD39 -> 0
B44: Grand Total | F44: =F42+F31 -> 1834.6667 | H44: =H42+H31 -> 702.43721 | I44: =I42+I31 -> 392.83333 | J44: =J42+J31 -> 434.80738 | K44: =K42+K31 -> 303 | L44: =L42+L31 -> 1833.0779 | P44: ='Workmen Category'!BW40 -> 0 | Q44: =Q42+Q31 -> 1685.125 | R44: ='Workmen Category'!BY40 -> 557.66667 | S44: ='Workmen Category'!BZ40 -> 274.5 | T44: ='Workmen Category'!CA40 -> 300 | U44: ='Workmen Category'!CB40 -> 571.04167 | V44: ='Workmen Category'!CC40 -> 1703.2083 | W44: ='Workmen Category'!CD40 -> 0
...

Sheet BP_Strucured
A1: Machine | B1: 46113 | C1: 46143 | D1: 46174 | E1: 46204 | F1: 46235 | G1: 46266 | H1: 46296 | I1: 46327 | J1: 46357 | K1: 46388 | L1: 46419 | M1: 46447 | N1: Units
A2: BCF | B2: 190053.56 | C2: 227636.66 | D2: 172736.18 | E2: 205578.85 | F2: 250826.71 | G2: 393717.01 | H2: 288952.27 | I2: 367132.62 | J2: 677193.28 | K2: 528044.36 | L2: 487687.57 | M2: 451556.32 | N2: kgs
A3: Cabling | B3: 1238788.5 | C3: 1080241.1 | D3: 960682.68 | E3: 1073640.3 | F3: 1193689.2 | G3: 1170212.4 | H3: 1054869.5 | I3: 940619.32 | J3: 1170039.7 | K3: 1163897.3 | L3: 1089413.4 | M3: 1033971.3 | N3: kgs
A4: Power Heat Set | B4: 100470.29 | C4: 77390.829 | D4: 46293.578 | E4: 73043.526 | F4: 77436.854 | G4: 86494.713 | H4: 79944.33 | I4: 125987.81 | J4: 124745.62 | K4: 137266.19 | L4: 131559.38 | M4: 129051.08 | N4: kgs
A5: Superba Heat Set | B5: 1108335.2 | C5: 1028009.1 | D5: 939711.64 | E5: 1001669.9 | F5: 1130540.2 | G5: 1056371.1 | H5: 933369.03 | I5: 920141.58 | J5: 1212098.6 | K5: 992702.54 | L5: 995401.92 | M5: 941464.77 | N5: kgs
A6: POY | B6: 1518410 | C6: 1270519.7 | D6: 1070367.6 | E6: 1503729.6 | F6: 1172241.6 | G6: 1069542.6 | H6: 1159497.9 | I6: 1031857.8 | J6: 1045049.7 | K6: 1046607.1 | L6: 999863.76 | M6: 921180.85 | N6: kgs
A7: Texturizing | B7: 1442558.3 | C7: 1246077.2 | D7: 1159707 | E7: 1249148.5 | F7: 1337464.4 | G7: 1140459.2 | H7: 1164411 | I7: 1032182.3 | J7: 1044370.1 | K7: 1045506.5 | L7: 998580.62 | M7: 924243 | N7: kgs
A8: Parallel Winding | B8: 772731.27 | C8: 674690.76 | D8: 607856.38 | E8: 697292.18 | F8: 657301.78 | G8: 634553.79 | H8: 615480.77 | I8: 549635.61 | J8: 663525.89 | K8: 633577.84 | L8: 603487.24 | M8: 608598.74 | N8: kgs
A9: Multiply | B9: 96546.648 | C9: 133921.53 | D9: 145860.51 | E9: 105972.23 | F9: 150546.85 | G9: 135954.38 | H9: 147220.99 | I9: 212414.35 | J9: 222519.97 | K9: 119372.29 | L9: 156342.53 | M9: 110249.83 | N9: kgs
A10: Autoclave | B10: 72130.301 | C10: 79680.976 | D10: 73191.572 | E10: 82743.929 | F10: 70744.122 | G10: 73504.265 | H10: 78371.572 | I10: 32784.196 | J10: 140570.75 | K10: 87002.911 | L10: 66645.339 | M10: 72988.029 | N10: kgs
A11: Assembly Winder | B11: 168676.95 | C11: 213602.51 | D11: 219052.09 | E11: 188716.16 | F11: 221290.97 | G11: 209458.64 | H11: 225592.56 | I11: 245198.55 | J11: 363090.72 | K11: 206375.2 | L11: 222987.87 | M11: 183237.85 | N11: kgs
A12: TFO | B12: 168676.95 | C12: 213602.51 | D12: 219052.09 | E12: 188716.16 | F12: 221290.97 | G12: 209458.64 | H12: 225592.56 | I12: 245198.55 | J12: 363090.72 | K12: 206375.2 | L12: 222987.87 | M12: 183237.85 | N12: kgs
... A19: CSP | B19: 460411.64 | C19: 318864.59 | D19: 276183.07 | E19: 375130.64 | F19: 636810.08 | G19: 340280.32 | H19: 290110.77 | I19: 238101.82 | J19: 162912.39 | K19: 144536.62 | L19: 179386.84 | M19: 197320.78 | N19: sqm
A20: Tufting

Sheet BP_Structured_edit
B1: 30 | C1: =31 -> 31 | D1: 30 | E1: 31 | F1: =31 -> 31 | G1: 30 | H1: =31 -> 31 | I1: 30 | J1: =31 -> 31 | K1: =31 -> 31 | L1: 28 | M1: =31 -> 31
B3: 46113 | C3: 46143 | D3: 46174 | E3: 46204 | F3: 46235 | G3: 46266 | H3: 46296 | I3: 46327 | J3: 46357 | K3: 46388 | L3: 46419 | M3: 46447 | N3: Total | O3: Avg/month
B4: 0 | C4: 0 | D4: 0 | E4: 0 | F4: 0 | G4: 0 | H4: 0 | I4: 0 | J4: 0 | K4: 0 | L4: 0 | M4: 0 | N4: 0 | O4: 0
B5: 93502.583 | C5: 156349.19 | D5: 155894.34 | E5: 240040.35 | F5: 252484.42 | G5: 425898.28 | H5: 295139.61 | I5: 373256.09 | J5: 347552.23 | K5: 430184.88 | L5: 295307.41 | M5: 322960.19 | N5: =SUM(B5:M5) -> 3388569.6 | O5: =N5/12 -> 282380.8
B6: 0 | C6: 0 | D6: 0 | E6: 0 | F6: 0 | G6: 0 | H6: 0 | I6: 0 | J6: 0 | K6: 0 | L6: 0 | M6: 0 | N6: 0 | O6: 0
B7: 3550.8556 | C7: 3104.1259 | D7: 4368.3216 | E7: 3014.3516 | F7: 4468.8351 | G7: 4754.4686 | H7: 8094.8686 | I7: 5637.3563 | J7: 4656.9542 | K7: 5187.7484 | L7: 8777.0581 | M7: 38294.036 | N7: =SUM(B7:M7) -> 93908.98 | O7: =N7/12 -> 7825.7483
B8: 0 | C8: 0 | D8: 0 | E8: 0 | F8: 0 | G8: 0 | H8: 0 | I8: 0 | J8: 0 | K8: 0 | L8: 0 | M8: 0 | N8: 0 | O8: 0
B9: 69765.141 | C9: 67837.092 | D9: 69765.997 | E9: 76270.706 | F9: 74616.141 | G9: 76560.417 | H9: 91231.484 | I9: 128904.55 | J9: 53179.57 | K9: 88747.834 | L9: 88747.834 | M9: 88747.834 | N9: =SUM(B9:M9) -> 974374.6 | O9: =N9/12 -> 81197.883
B10: 0 | C10: 0 | D10: 0 | E10: 0 | F10: 0 | G10: 0 | H10: 0 | I10: 0 | J10: 0 | K10: 0 | L10: 0 | M10: 0 | N10: 0 | O10: 0
B11: 49343.753 | C11: 52361.053 | D11: 55394.758 | E11: 50057.707 | F11: 46007.516 | G11: 45004.454 | H11: 45505.985 | I11: 51870.413 | J11: 33624.717 | K11: 44001.392 | L11: 41995.269 | M11: 41733.915 | N11: =SUM(B11:M11) -> 556900.93 | O11: =N11/12 -> 46408.411
H12: 0 | I12: 0 | J12: 0 | N12: 0 | O12: 0
H13: 0 | I13: 0 | J13: 0 | N13: 0 | O13: 0
A14: BCF | B14: 190053.56 | C14: 227636.66 | D14: 172736.18 | E14: 205578.85 | F14: 250826.71 | G14: 393717.01 | H14: 288952.27 | I14: 367132.62 | J14: 677193.28 | K14: 528044.36 | L14: 487687.57 | M14: 451556.32 | N14: =SUM(B14:M14) -> 4241115.4 | O14: =N14/12 -> 353426.28 | P14: =O14/30 -> 11780.876
B15: 646787.06 | C15: 668346.63 | D15: 646787.06 | E15: 668346.63 | F15: 646787.06 | G15: 668346.63 | H15: 668346.63 | I15: 646787.06 | J15: 668346.63 | K15: 668346.63 | L15: 603667.92 | M15: 668346.63 | N15: =SUM(B15:M15) -> 7869242.5 | O15: =N15/12 -> 655770.21
B17: 421624.73 | C17: 379395.17 | D17: 352363.65 | E17: 289663.51 | F17: 260210.15 | G17: 106829.01 | H17: 219074.68 | I17: 78118.644 | J17: 220033.16 | K17: 90924.771 | L17: 160440.35 | M17: 167310.66 | N17: =SUM(B17:M17) -> 2745988.5 | O17: =N17/12 -> 228832.37
B19: 0.65187564 | C19: 0.56766228 | D19: 0.54479081 | E19: 0.43340311 | F19: 0.40231192 | G19: 0.15984072 | H19: 0.32778602 | I19: 0.12077954 | J19: 0.32922012 | K19: 0.13604433 | L19: 0.26577584 | M19: 0.25033516 | O19: 0.39903933
B22: 0 | C22: 0 | D22: 0 | E22: 0 | F22: 0 | G22: 0 | H22: 0 | I22: 0 | J22: 0 | K22: 0 | L22: 0 | M22: 0 | N22: 0 | O22: 0
B23: 73225.991 | C23: 119752.5 | D23: 139402.93 | E23: 204824.9 | F23: 230734.55 | G23: 351640.95 | H23: 273657.31 | I23: 332524.17 | J23: 252165.31 | K23: 312268.52 | L23: 236283.51 | M23: 310873.84 | N23: 2837354.5 | O23: 236446.21
B24: 0 | C24: 0 | D24: 0 | E24: 0 | F24: 0 | G24: 0 | H24: 0 | I24: 0 | J24: 0 | K24: 0 | L24: 0 | M24: 0 | N24: 0 | O24: 0
B25: 74880.268 | C25: 47432.121 | D25: 54501.178 | E25: 52934.512 | F25: 63570.312 | G25: 51770.758 | H25: 59857.719 | I25: 58618.213 | J25: 46326.396 | K25: 53846.918 | L25: 69556 | M25: 400974.37 | N25: 1034268.8 | O25: 86189.064
B26: 0 | C26: 0 | D26: 0 | E26: 0 | F26: 0 | G26: 0 | H26: 0 | I26: 0 | J26: 0 | K26: 0 | L26: 0 | M26: 0 | N26: 0 | O26: 0
B27: 24226.279 | C27: 24226.279 | D27: 24226.279 | E27: 27980.323 | F27: 27980.323 | G27: 27980.323 | H27: 31708.45 | I27: 31708.45 | J27: 31708.45 | K27: 29481.893 | L27: 29481.893 | M27: 29481.893 | N27: 340190.84 | O27: 28349.236
B28: 0 | C28: 0 | D28: 0 | E28: 0 | F28: 0 | G28: 0 | H28: 0 | I28: 0 | J28: 0 | K28: 0 | L28: 0 | M28: 0 | N28: 0 | O28: 0
B29: 500285.87 | C29: 547076.73 | D29: 497638.64 | E29: 587007.99 | F29: 553891.09 | G29: 578657.39 | H29: 401379.11 | I29: 561813.2 | J29: 581515.61 | K29: 530280.42 | L29: 535627.22 | M29: 527711.44 | N29: 6402884.7 | O29: 533573.73
A30: Cabling | B30: 1238788.5 | C30: 1080241.1 | D30: 960682.68 | E30: 1073640.3 | F30: 1193689.2 | G30: 1170212.4 | H30: 1054869.5 | I30: 940619.32 | J30: 1170039.7 | K30: 1163897.3 | L30: 1089413.4 | M30: 1033971.3 | N30: =SUM(B30:M30) -> 13170065 | P30: =O30/30 -> 0
B31: 0 | C31: 0 | D31: 0 | E31: 0 | F31: 0 | G31: 0 | H31: 0 | I31: 0 | J31: 0 | K31: 0 | L31: 0 | M31: 0 | N31: 0 | O31: 0
B32: 0 | C32: 0 | D32: 0 | E32: 0 | F32: 0 | G32: 0 | H32: 0 | I32: 0 | J32: 0 | K32: 0 | L32: 0 | M32: 0 | N32: 0 | O32: 0
B33: 1077934.5 | C33: 1113865.6 | D33: 1077934.5 | E33: 1113865.6 | F33: 1077934.5 | G33: 1113865.6 | H33: 1113865.6 | I33: 1077934.5 | J33: 1113865.6 | K33: 1113865.6 | L33: 1006072.2 | M33: 1113865.6 | N33: 13114869 | O33: 1092905.8
B34: 405316.06 | C34: 375377.99 | D34: 362165.44 | E34: 241117.89 | F34: 201758.2 | G34: 103816.2 | H34: 347263.02 | I34: 93270.439 | J34: 202149.85 | K34: 187987.87 | L34: 135123.54 | M34: -155175.92 | N34: 2500170.6 | O34: 208347.55
B35: 0 | C35: 0 | D35: 0 | N35: 0 | O35: 0
B36: 22420.613 | C36: 23822.182 | D36: 23858.968 | E36: 28153.152 | F36: 29205.876 | G36: 32582.239 | H36: 24729.116 | I36: 32822.134 | J36: 29410.186 | K36: 29867.024 | L36: 31105.308 | M36: 40936.824 | N36: 348913.62 | O36: 29076.135
B37: 672618.4 | C37: 738487.63 | D37: 715769.03 | E37: 872747.73 | F37: 876176.27 | G37: 1010049.4 | H37: 766602.59 | I37: 984664.03 | J37: 911715.76 | K37: 925877.75 | L37: 870948.63 | M37: 1269041.5 | N37: 10614699 | O37: 884558.23
B38: 22420.613 | C38: 23822.182 | D38: 23858.968 | E38: 28153.152 | F38: 29205.876 | G38: 32582.239 | H38: 24729.116 | I38: 32822.134 | J38: 29410.186 | K38: 29867.024 | L38: 31105.308 | M38: 40936.824 | N38: 348913.62 | O38: 29076.135
B39: 0.37601179 | C39: 0.33700473 | D39: 0.33598094 | E39: 0.21646946 | F39: 0.18717112 | G39: 0.093203521 | H39: 0.31176384 | I39: 0.086527003 | J39: 0.18148496 | K39: 0.16877069 | L39: 0.134308 | M39: -0.13931297 | O39: 0.19063633
B41: 0 | C41: 0 | D41: 0 | E41: 0 | F41: 0 | G41: 0 | H41: 0 | I41: 0 | J41: 0 | K41: 0 | L41: 0 | M41: 0 | N41: 0 | O41: 0
B42: 12842.152 | C42: 49703.587 | D42: 72948.36 | E42: 77053.363 | F42: 87932.922 | G42: 147412.56 | H42: 116284.38 | I42: 81541.796 | J42: 147545.03 | K42: 89597.309 | L42: 110332.44 | M42: 123683.37 | N42: 1116877.3 | O42: 93073.106
B43: 0 | C43: 0 | D43: 0 | E43: 0 | F43: 0 | G43: 0 | H43: 0 | I43: 0 | J43: 0 | K43: 0 | L43: 0 | M43: 0 | N43: 0 | O43: 0
B44: 0 | C44: 0 | D44: 0 | E44: 0 | F44: 0 | G44: 0 | H44: 0 | I44: 0 | J44: 0 | K44: 0 | L44: 0 | M44: 0 | N44: 0 | O44: 0
B45: 0 | C45: 0 | D45: 0 | E45: 0 | F45: 0 | G45: 0 | H45: 0 | I45: 0 | J45: 0 | K45: 0 | L45: 0 | M45: 0 | N45: 0 | O45: 0
B46: 0 | C46: 0 | D46: 0 | E46: 0 | F46: 0 | G46: 0 | H46: 0 | I46: 0 | J46: 0 | K46: 0 | L46: 0 | M46: 0 | N46: 0 | O46: 0
...

Sheet Sectionwise Working
A3: Section | B3: Machine | C3: Month | D3: Avg. Speed | E3: Avg. Denier | F3: Total Spindle | G3: Utilization | H3: Efficiency | I3: Capacity Per Day | J3: BP | L3: Spinder Req. | M3: Spinder Req. | N3: Winder Req. | O3: Winder Req. | P3: MP Req./Shift | Q3: MP Req./Day | R3: MP Req./Day | S3: Standard HC (Fix) | T3: Total Manpower Req. | U3: Capacity/machine | V3: Available M/C | W3: Available Spindles | X3: Req. M/C | Y3: Req. Spindles | Z3: HC Deployed/M/C | AA3: Total HC Req. /Shift | AB3: Total HC Req. /Shift | AC3: Total HC Req. /Day | AD3: Remarks | AF3: Line | AG3: Winder | AH3: Ends | AN3: Associate | AO3: NAPS | AP3: CLM MD | AW3: Avg MP | AY3: 45748 | AZ3: 45778 | BA3: 45809 | BB3: 45839 | BC3: 45870 | BD3: 45901 | BE3: 45931 | BF3: 45962 | BG3: 45992 | BH3: 46023 | BI3: 46054 | BJ3: 46082
A4: 2. BCF | B4: 2. BCF | C4: 46113 | D4: ='YN01'!$J$31 -> 2576.9311 | E4: ='YN01'!$B$31 -> 1247.7786 | F4: 48 | G4: ='YN01'!$H$10 -> 0.93424658 | H4: ='YN01'!$I$10 -> 0.94 | I4: =D4*E4*F4*G4*H4*0.00016 -> 21686.572 | J4: =BP!E14/DAY(EOMONTH(C4,0)) -> 6335.1186 | L4: =J4/I4 -> 0.29212171 | M4: =L4*F4 -> 14.021842 | N4: =M4/3 -> 4.6739474 | O4: =ROUNDUP(N4,0) -> 5 | P4: =O4/2.5 -> 2 | Q4: =P4*3 -> 6 | R4: =ROUNDUP(Q4,0) -> 6 | S4: ='Manpower Allocation'!$D$9 -> 17 | T4: =R4+S4 -> 23 | U4: =I4/V4 -> 2710.8215 | V4: 8 | W4: =8*2*3 -> 48 | X4: =IF(J4>I4,V4,J4/U4) -> 2.3369737 | Y4: =ROUND(L4*W4,0) -> 14 | Z4: 0.8 | AA4: =X4*Z4 -> 1.869579 | AB4: =ROUNDUP(AA4,0) -> 2 | AC4: =AB4*3 -> 6 | AD4: 1 M/C ~ 6 Spindle (Ends) = 1 Opt ~ 7.5 Spindles (Ends) | AF4: Tri color | AG4: 3 | AH4: =AG4*3 -> 9 | AI4: 2 HC/Shift | AN4: 24 | AO4: =T4-AN4-AP4 -> -4 | AP4: 3 | AT4: =(5*3)+'Manpower Allocation'!G9 -> 15 | AU4: Operator | AV4: =R31 -> 11.166667 | AW4: =AW13/2*3 -> 15 | AX4: For 10 Winders | AY4: =AY13/2*3 -> 9 | AZ4: =AZ13/2*3 -> 10.5 | BA4: =BA13/2*3 -> 10.5 | BB4: =BB13/2*3 -> 13.5 | BC4: =BC13/2*3 -> 13.5 | BD4: =BD13/2*3 -> 19.5 | BE4: =BE13/2*3 -> 16.5 | BF4: =BF13/2*3 -> 21 | ... BJ4: =BJ13/2*3 -> 18
A5: 2. BCF | B5: 2. BCF | C5: 46143 | D5: ='YN01'!$J$31 -> 2576.9311 | E5: ='YN01'!$B$31 -> 1247.7786 | F5: 48 | G5: ='YN01'!$H$10 -> 0.93424658 | H5: ='YN01'!$I$10 -> 0.94 | I5: =D5*E5*F5*G5*H5*0.00016 -> 21686.572 | J5: =BP!F14/DAY(EOMONTH(C5,0)) -> 7343.1179 | L5: =J5/I5 -> 0.33860206 | M5: =L5*F5 -> 16.252899 | N5: =M5/3 -> 5.4176329 | O5: =ROUNDUP(N5,0) -> 6 | P5: =O5/2.5 -> 2.4 | Q5: =P5*3 -> 7.2 | R5: =ROUNDUP(Q5,0) -> 8 | S5: ='Manpower Allocation'!$D$9 -> 17 | T5: =R5+S5 -> 25 | U5: =I5/V5 -> 2710.8215 | V5: 8 | W5: =8*2*3 -> 48 | X5: =IF(J5>I5,V5,J5/U5) -> 2.7088165 | Y5: =ROUND(L5*W5,0) -> 16 | Z5: 0.8 | AA5: =X5*Z5 -> 2.1670532 | AB5: =ROUNDUP(AA5,0) -> 3 | AC5: =ROUNDUP(AA5*3,0) -> 7 | AD5: =IF(MOD(AA5,1)<0.3,ROUNDUP(AA5*3,0),AB5*3) -> 7 | AE5: =IF(MOD(X5*Z5,1)<0.3,ROUNDUP(X5*Z5*3,0),ROUNDUP(X5*Z5,0)*3) -> 7 | AF5: Mono 1 | AG5: 2 | AH5: =AG5*3 -> 6 | AI5: 1 HC/Shift | AN5: 24 | AO5: =T5-AN5-AP5 -> -2 | AP5: 3 | AU5: Material Handling | AV5: 3 | AW5: 3 | AY5: 3 | AZ5: 3 | BA5: 3 | BB5: 3 | BC5: 3 | BD5: 3 | BE5: 3 | BF5: 3 | BG5: 3 | BH5: 3 | BI5: 3 | BJ5: 3
A6: 2. BCF | B6: 2. BCF | C6: 46174 | D6: ='YN01'!$J$31 -> 2576.9311 | E6: ='YN01'!$B$31 -> 1247.7786 | F6: 48 | G6: ='YN01'!$H$10 -> 0.93424658 | H6: ='YN01'!$I$10 -> 0.94 | I6: =D6*E6*F6*G6*H6*0.00016 -> 21686.572 | J6: =BP!G14/DAY(EOMONTH(C6,0)) -> 5757.8727 | L6: =J6/I6 -> 0.26550405 | M6: =L6*F6 -> 12.744194 | N6: =M6/3 -> 4.2480648 | O6: =ROUNDUP(N6,0) -> 5 | P6: =O6/2.5 -> 2 | Q6: =P6*3 -> 6 | R6: =ROUNDUP(Q6,0) -> 6 | S6: ='Manpower Allocation'!$D$9 -> 17 | T6: =R6+S6 -> 23 | U6: =I6/V6 -> 2710.8215 | V6: 8 | W6: =8*2*3 -> 48 | X6: =IF(J6>I6,V6,J6/U6) -> 2.1240324 | Y6: =ROUND(L6*W6,0) -> 13 | Z6: 0.8 | AA6: =X6*Z6 -> 1.6992259 | AB6: =ROUNDUP(AA6,0) -> 2 | AC6: =AB6*3 -> 6 | AD6: =IF(MOD(AA6,1)<0.3,ROUNDUP(AA6*3,0),AB6*3) -> 6 | AE6: =IF(MOD(X6*Z6,1)<0.3,ROUNDUP(X6*Z6*3,0),ROUNDUP(X6*Z6,0)*3) -> 6 | AF6: Mono 2 | AG6: 2 | AH6: =AG6*3 -> 6 | AI6: 1 HC/Shift | AN6: 24 | AO6: =T6-AN6-AP6 -> -4 | AP6: 3 | AU6: Spinning - Operator | AV6: 6 | AW6: =3*2-1 -> 5 | AY6: =3*2-1 -> 5 | AZ6: =3*2-1 -> 5 | BA6: =3*2-1 -> 5 | BB6: =3*2-1 -> 5 | BC6: =3*2-1 -> 5 | BD6: =3*2-1 -> 5 | BE6: =3*2-1 -> 5 | BF6: =3*2-1 -> 5 | ... BJ6: =3*2-1 -> 5
A7: 2. BCF | B7: 2. BCF | C7: 46204 | D7: ='YN01'!$J$31 -> 2576.9311 | E7: ='YN01'!$B$31 -> 1247.7786 | F7: 48 | G7: ='YN01'!$H$10 -> 0.93424658 | H7: ='YN01'!$I$10 -> 0.94 | I7: =D7*E7*F7*G7*H7*0.00016 -> 21686.572 | J7: =BP!H14/DAY(EOMONTH(C7,0)) -> 6631.5757 | L7: =J7/I7 -> 0.30579179 | M7: =L7*F7 -> 14.678006 | N7: =M7/3 -> 4.8926687 | O7: =ROUNDUP(N7,0) -> 5 | P7: =O7/2.5 -> 2 | Q7: =P7*3 -> 6 | R7: =ROUNDUP(Q7,0) -> 6 | S7: ='Manpower Allocation'!$D$9 -> 17 | T7: =R7+S7 -> 23 | U7: =I7/V7 -> 2710.8215 | V7: 8 | W7: =8*2*3 -> 48 | X7: =IF(J7>I7,V7,J7/U7) -> 2.4463343 | Y7: =ROUND(L7*W7,0) -> 15 | Z7: 0.8 | AA7: =X7*Z7 -> 1.9570675 | AB7: =ROUNDUP(AA7,0) -> 2 | AC7: =AB7*3 -> 6 | AD7: =IF(MOD(AA7,1)<0.3,ROUNDUP(AA7*3,0),AB7*3) -> 6 | AE7: =IF(MOD(X7*Z7,1)<0.3,ROUNDUP(X7*Z7*3,0),ROUNDUP(X7*Z7,0)*3) -> 6 | AF7: Mono 3 | AG7: 2 | AH7: =AG7*3 -> 6 | AI7: 1 HC/Shift | AN7: 24 | AO7: =T7-AN7-AP7 -> -4 | AP7: 3 | AU7: Data Entry | AV7: 2 | AW7: 1 | AX7: ** Workload of DEO should be Digitized. And Shared with Spinning Operator | AY7: 1 | AZ7: 1 | BA7: 1 | BB7: 1 | BC7: 1 | BD7: 1 | BE7: 1 | BF7: 1 | BG7: 1 | BH7: 1 | BI7: 1 | BJ7: 1
A8: 2. BCF | B8: 2. BCF | C8: 46235 | D8: ='YN01'!$J$31 -> 2576.9311 | E8: ='YN01'!$B$31 -> 1247.7786 | F8: 48 | G8: ='YN01'!$H$10 -> 0.93424658 | H8: ='YN01'!$I$10 -> 0.94 | I8: =D8*E8*F8*G8*H8*0.00016 -> 21686.572 | J8: =BP!I14/DAY(EOMONTH(C8,0)) -> 8091.1841 | L8: =J8/I8 -> 0.3730965 | M8: =L8*F8 -> 17.908632 | N8: =M8/3 -> 5.969544 | O8: =ROUNDUP(N8,0) -> 6 | P8: =O8/2.5 -> 2.4 | Q8: =P8*3 -> 7.2 | R8: =ROUNDUP(Q8,0) -> 8 | S8: ='Manpower Allocation'!$D$9 -> 17 | T8: =R8+S8 -> 25 | U8: =I8/V8 -> 2710.8215 | V8: 8 | W8: =8*2*3 -> 48 | X8: =IF(J8>I8,V8,J8/U8) -> 2.984772 | Y8: =ROUND(L8*W8,0) -> 18 | Z8: 0.8 | AA8: =X8*Z8 -> 2.3878176 | AB8: =ROUNDUP(AA8,0) -> 3 | AC8: =AB8*3 -> 9 | AD8: =IF(MOD(AA8,1)<0.3,ROUNDUP(AA8*3,0),AB8*3) -> 9 | AE8: =IF(MOD(X8*Z8,1)<0.3,ROUNDUP(X8*Z8*3,0),ROUNDUP(X8*Z8,0)*3) -> 9 | AF8: Mono 4 | AG8: 2 | AH8: =AG8*3 -> 6 | AI8: 1 HC/Shift | AN8: 24 | AO8: =T8-AN8-AP8 -> -2 | AP8: 3 | AU8: G-Burnout | AV8: 5 | AW8: 5 | AY8: 5 | AZ8: 5 | BA8: 5 | BB8: 5 | BC8: 5 | BD8: 5 | BE8: 5 | BF8: 5 | BG8: 5 | BH8: 5 | BI8: 5 | BJ8: 5
A9: 2. BCF | B9: 2. BCF | C9: 46266 | D9: ='YN01'!$J$31 -> 2576.9311 | E9: ='YN01'!$B$31 -> 1247.7786 | F9: 48 | G9: ='YN01'!$H$10 -> 0.93424658 | H9: ='YN01'!$I$10 -> 0.94 | I9: =D9*E9*F9*G9*H9*0.00016 -> 21686.572 | J9: =BP!J14/DAY(EOMONTH(C9,0)) -> 13123.9 | L9: =J9/I9 -> 0.60516251 | M9: =L9*F9 -> 29.0478 | N9: =M9/3 -> 9.6826001 | O9: =ROUNDUP(N9,0) -> 10 | P9: =O9/2.5 -> 4 | Q9: =P9*3 -> 12 | R9: =ROUNDUP(Q9,0) -> 12 | S9: ='Manpower Allocation'!$D$9 -> 17 | T9: =R9+S9 -> 29 | U9: =I9/V9 -> 2710.8215 | V9: 8 | W9: =8*2*3 -> 48 | X9: =IF(J9>I9,V9,J9/U9) -> 4.8413001 | Y9: =ROUND(L9*W9,0) -> 29 | Z9: 0.8 | AA9: =X9*Z9 -> 3.8730401 | AB9: =ROUNDUP(AA9,0) -> 4 | AC9: =AB9*3 -> 12 | AD9: =IF(MOD(AA9,1)<0.3,ROUNDUP(AA9*3,0),AB9*3) -> 12 | AE9: =IF(MOD(X9*Z9,1)<0.3,ROUNDUP(X9*Z9*3,0),ROUNDUP(X9*Z9,0)*3) -> 12 | AF9: Mono 5 | AG9: 2 | AH9: =AG9*3 -> 6 | AI9: 1 HC/Shift | AN9: 30 | AO9: =T9-AN9-AP9 -> -4 | AP9: 3 | AU9: H-DRYER (BCF+POY) | AV9: 5 | AW9: 5 | AY9: 5 | AZ9: 5 | BA9: 5 | BB9: 5 | BC9: 5 | BD9: 5 | BE9: 5 | BF9: 5 | BG9: 5 | BH9: 5 | BI9: 5 | BJ9: 5
A10: 2. BCF | B10: 2. BCF | C10: 46296 | D10: ='YN01'!$J$31 -> 2576.9311 | E10: ='YN01'!$B$31 -> 1247.7786 | F10: 48 | G10: ='YN01'!$H$10 -> 0.93424658 | H10: ='YN01'!$I$10 -> 0.94 | I10: =D10*E10*F10*G10*H10*0.00016 -> 21686.572 | J10: =BP!K14/DAY(EOMONTH(C10,0)) -> 9321.041 | L10: =J10/I10 -> 0.42980702 | M10: =L10*F10 -> 20.630737 | N10: =M10/3 -> 6.8769124 | O10: =ROUNDUP(N10,0) -> 7 | P10: =O10/2.5 -> 2.8 | Q10: =P10*3 -> 8.4 | R10: =ROUNDUP(Q10,0) -> 9 | S10: ='Manpower Allocation'!$D$9 -> 17 | T10: =R10+S10 -> 26 | U10: =I10/V10 -> 2710.8215 | V10: 8 | W10: =8*2*3 -> 48 | X10: =IF(J10>I10,V10,J10/U10) -> 3.4384562 | Y10: =ROUND(L10*W10,0) -> 21 | Z10: 0.8 | AA10: =X10*Z10 -> 2.750765 | AB10: =ROUNDUP(AA10,0) -> 3 | AC10: =AB10*3 -> 9 | AD10: =IF(MOD(AA10,1)<0.3,ROUNDUP(AA10*3,0),AB10*3) -> 9 | AE10: =IF(MOD(X10*Z10,1)<0.3,ROUNDUP(X10*Z10*3,0),ROUNDUP(X10*Z10,0)*3) -> 9 | AF10: Mono 6 | AG10: 2 | AH10: =AG10*3 -> 6 | AI10: 1 HC/Shift | AN10: 30 | AO10: =T10-AN10-AP10 -> -7 | AP10: 3 | AU10: Chips Charging | AV10: 3 | AW10: 3 | AY10: 3 | AZ10: 3 | BA10: 3 | BB10: 3 | BC10: 3 | BD10: 3 | BE10: 3 | BF10: 3 | BG10: 3 | BH10: 3 | BI10: 3 | BJ10: 3
A11: 2. BCF | B11: 2. BCF | C11: 46327 | D11: ='YN01'!$J$31 -> 2576.9311 | E11: ='YN01'!$B$31 -> 1247.7786 | F11: 48 | G11: ='YN01'!$H$10 -> 0.93424658 | H11: ='YN01'!$I$10 -> 0.94 | I11: =D11*E11*F11*G11*H11*0.00016 -> 21686.572 | J11: =BP!L14/DAY(EOMONTH(C11,0)) -> 12237.754 | L11: =J11/I11 -> 0.56430099 | M11: =L11*F11 -> 27.086448 | N11: =M11/3 -> 9.0288158 | O11: =ROUNDUP(N11,0) -> 10 | P11: =O11/2.5 -> 4 | Q11: =P11*3 -> 12 | R11: =ROUNDUP(Q11,0) -> 12 | S11: ='Manpower Allocation'!$D$9 -> 17 | T11: =R11+S11 -> 29 | U11: =I11/V11 -> 2710.8215 | V11: 8 | W11: =8*2*3 -> 48 | X11: =IF(J11>I11,V11,J11/U11) -> 4.5144079 | Y11: =ROUND(L11*W11,0) -> 27 | Z11: 0.8 | AA11: =X11*Z11 -> 3.6115263 | AB11: =ROUNDUP(AA11,0) -> 4 | AC11: =AB11*3 -> 12 | AD11: =IF(MOD(AA11,1)<0.3,ROUNDUP(AA11*3,0),AB11*3) -> 12 | AE11: =IF(MOD(X11*Z11,1)<0.3,ROUNDUP(X11*Z11*3,0),ROUNDUP(X11*Z11,0)*3) -> 12 | AF11: BI Component | AG11: 1 | AH11: =AG11*3 -> 3 | AI11: 1 HC/Shift | AN11: 30 | AO11: =T11-AN11-AP11 -> -4 | AP11: 3 | AU11: TOTAL | AV11: =SUM(AV4:AV10) -> 35.166667 | AW11: =SUM(AW4:AW10) -> 37 | AY11: =SUM(AY4:AY10) -> 31 | AZ11: =SUM(AZ4:AZ10) -> 32.5 | BA11: =SUM(BA4:BA10) -> 32.5 | BB11: =SUM(BB4:BB10) -> 35.5 | BC11: =SUM(BC4:BC10) -> 35.5 | BD11: =SUM(BD4:BD10) -> 41.5 | BE11: =SUM(BE4:BE10) -> 38.5 | BF11: =SUM(BF4:BF10) -> 43 | ... BJ11: =SUM(BJ4:BJ10) -> 40
A12: 2. BCF | B12: 2. BCF | C12: 46357 | D12: ='YN01'!$J$31 -> 2576.9311 | E12: ='YN01'!$B$31 -> 1247.7786 | F12: 48 | G12: ='YN01'!$H$10 -> 0.93424658 | H12: ='YN01'!$I$10 -> 0.94 | I12: =D12*E12*F12*G12*H12*0.00016 -> 21686.572 | J12: =BP!M14/DAY(EOMONTH(C12,0)) -> 21844.945 | L12: =J12/I12 -> 1.0073028 | M12: =L12*F12 -> 48.350534 | N12: =M12/3 -> 16.116845 | O12: =ROUNDUP(N12,0) -> 17 | P12: =O12/2.5 -> 6.8 | Q12: =P12*3 -> 20.4 | R12: =ROUNDUP(Q12,0) -> 21 | S12: ='Manpower Allocation'!$D$9 -> 17 | T12: =R12+S12 -> 38 | U12: =I12/V12 -> 2710.8215 | V12: 8 | W12: =8*2*3 -> 48 | X12: =IF(J12>I12,V12,J12/U12) -> 8 | Y12: =ROUND(L12*W12,0) -> 48 | Z12: 0.8 | AA12: =X12*Z12 -> 6.4 | AB12: =ROUNDUP(AA12,0) -> 7 | AC12: =AB12*3 -> 21 | AD12: =IF(MOD(AA12,1)<0.3,ROUNDUP(AA12*3,0),AB12*3) -> 21 | AE12: =IF(MOD(X12*Z12,1)<0.3,ROUNDUP(X12*Z12*3,0),ROUNDUP(X12*Z12,0)*3) -> 21 | AN12: 30 | AO12: =T12-AN12-AP12 -> 5 | AP12: 3 | CI12: Yarn | CJ12: 3
A13: 2. BCF | B13: 2. BCF | C13: 46388 | D13: ='YN01'!$J$31 -> 2576.9311 | E13: ='YN01'!$B$31 -> 1247.7786 | F13: 48 | G13: ='YN01'!$H$10 -> 0.93424658 | H13: ='YN01'!$I$10 -> 0.94 | I13: =D13*E13*F13*G13*H13*0.00016 -> 21686.572 | J13: =BP!N14/DAY(EOMONTH(C13,0)) -> 17033.689 | L13: =J13/I13 -> 0.78544866 | M13: =L13*F13 -> 37.701536 | N13: =M13/3 -> 12.567179 | O13: =ROUNDUP(N13,0) -> 13 | P13: =O13/2.5 -> 5.2 | Q13: =P13*3 -> 15.6 | R13: =ROUNDUP(Q13,0) -> 16 | S13: ='Manpower Allocation'!$D$9 -> 17 | T13: =R13+S13 -> 33 | U13: =I13/V13 -> 2710.8215 | V13: 8 | W13: =8*2*3 -> 48 | X13: =IF(J13>I13,V13,J13/U13) -> 6.2835893 | Y13: =ROUND(L13*W13,0) -> 38 | Z13: 0.8 | AA13: =X13*Z13 -> 5.0268715 | AB13: =ROUNDUP(AA13,0) -> 6 | AC13: =ROUNDUP(AA13*3,0) -> 16 | AD13: =IF(MOD(AA13,1)<0.3,ROUNDUP(AA13*3,0),AB13*3) -> 16 | AE13: =IF(MOD(X13*Z13,1)<0.3,ROUNDUP(X13*Z13*3,0),ROUNDUP(X13*Z13,0)*3) -> 16 | AN13: 30 | AO13: =T13-AN13-AP13 -> 0 | AP13: 3 | AW13: 10 | AY13: 6 | AZ13: 7 | BA13: 7 | BB13: 9 | BC13: 9 | BD13: 13 | BE13: 11 | BF13: 14 | BG13: 11 | BH13: 14 | BI13: 11 | BJ13: 12 | CI13: Tufting | CJ13: 3
A14: 2. BCF | B14: 2. BCF | C14: 46419 | D14: ='YN01'!$J$31 -> 2576.9311 | E14: ='YN01'!$B$31 -> 1247.7786 | F14: 48 | G14: ='YN01'!$H$10 -> 0.93424658 | H14: ='YN01'!$I$10 -> 0.94 | I14: =D14*E14*F14*G14*H14*0.00016 -> 21686.572 | J14: =BP!O14/DAY(EOMONTH(C14,0)) -> 17417.413 | L14: =J14/I14 -> 0.80314275 | M14: =L14*F14 -> 38.550852 | N14: =M14/3 -> 12.850284 | O14: =ROUNDUP(N14,0) -> 13 | P14: =O14/2.5 -> 5.2 | Q14: =P14*3 -> 15.6 | R14: =ROUNDUP(Q14,0) -> 16 | S14: ='Manpower Allocation'!$D$9 -> 17 | T14: =R14+S14 -> 33 | U14: =I14/V14 -> 2710.8215 | V14: 8 | W14: =8*2*3 -> 48 | X14: =IF(J14>I14,V14,J14/U14) -> 6.425142 | Y14: =ROUND(L14*W14,0) -> 39 | Z14: 0.8 | AA14: =X14*Z14 -> 5.1401136 | AB14: =ROUNDUP(AA14,0) -> 6 | AC14: =ROUNDUP(AA14*3,0) -> 16 | AD14: =IF(MOD(AA14,1)<0.3,ROUNDUP(AA14*3,0),AB14*3) -> 16 | AE14: =IF(MOD(X14*Z14,1)<0.3,ROUNDUP(X14*Z14*3,0),ROUNDUP(X14*Z14,0)*3) -> 16 | AN14: 30 | AO14: =T14-AN14-AP14 -> 0 | AP14: 3 | CI14: Coating | CJ14: 3
A15: 2. BCF | B15: 2. BCF | C15: 46447 | D15: ='YN01'!$J$31 -> 2576.9311 | E15: ='YN01'!$B$31 -> 1247.7786 | F15: 48 | G15: ='YN01'!$H$10 -> 0.93424658 | H15: ='YN01'!$I$10 -> 0.94 | I15: =D15*E15*F15*G15*H15*0.00016 -> 21686.572 | J15: =BP!P14/DAY(EOMONTH(C15,0)) -> 14566.333 | L15: =J15/I15 -> 0.67167521 | M15: =L15*F15 -> 32.24041 | N15: =M15/3 -> 10.746803 | O15: =ROUNDUP(N15,0) -> 11 | P15: =O15/2.5 -> 4.4 | Q15: =P15*3 -> 13.2 | R15: =ROUNDUP(Q15,0) -> 14 | S15: ='Manpower Allocation'!$D$9 -> 17 | T15: =R15+S15 -> 31 | U15: =I15/V15 -> 2710.8215 | V15: 8 | W15: =8*2*3 -> 48 | X15: =IF(J15>I15,V15,J15/U15) -> 5.3734017 | Y15: =ROUND(L15*W15,0) -> 32 | Z15: 0.8 | AA15: =X15*Z15 -> 4.2987214 | AB15: =ROUNDUP(AA15,0) -> 5 | AC15: =ROUNDUP(AA15*3,0) -> 13 | AD15: =IF(MOD(AA15,1)<0.3,ROUNDUP(AA15*3,0),AB15*3) -> 13 | AE15: =IF(MOD(X15*Z15,1)<0.3,ROUNDUP(X15*Z15*3,0),ROUNDUP(X15*Z15,0)*3) -> 13 | AN15: 30 | AO15: =T15-AN15-AP15 -> -2 | AP15: 3 | CI15: CSP | CJ15: 3
A17: Section | B17: Machine | C17: Month | D17: Avg. Speed | E17: Avg. Denier | F17: Total Spindle | G17: Utilization | H17: Efficiency | I17: Capacity Per Day | J17: BP | L17: Spinder Req. | M17: Spinder Req. | N17: Winder Req. | O17: Winder Req. | P17: MP Req./Shift | Q17: MP Req./Day | R17: MP Req./Day | S17: Standard HC (Fix) | T17: Total Manpower Req. | U17: Capacity/machine | V17: Available Line | W17: Available Spindles | X17: Req. M/C | Y17: Req. Spindles | Z17: HC Deployed/M/C | AA17: Total HC Req. /Shift | AB17: Total HC Req. /Shift | AC17: Total HC Req. /Day | AD17: Remarks | AE17: =AVERAGE(AE18:AE29) -> 71.166667 | AF17: Line | AG17: Winder | AH17: Ends | AJ17: =AVERAGE(AJ18:AJ29) -> 71.166667 | AW17: Avg MP | AY17: 45748 | AZ17: 45778 | BA17: 45809 | BB17: 45839 | BC17: 45870 | BD17: 45901 | BE17: 45931 | BF17: 45962 | BG17: 45992 | BH17: 46023 | BI17: 46054 | BJ17: 46082
A18: 1. POY | B18: 1. POY | C18: 46113 | D18: ='YN01'!$J$51 -> 2967.7287 | E18: ='YN01'!$B$51 -> 270.46771 | F18: =24*12-12 -> 276 | G18: ='YN01'!$H$43 -> 0.93424658 | H18: ='YN01'!$I$43 -> 0.97 | I18: =D18*E18*F18*G18*H18*0.00016 -> 32121.952 | J18: =(BP!E90+BP!E91)/DAY(EOMONTH(C18,0)) -> 50613.668 | L18: =J18/I18 -> 1.5756722 | M18: =IF((L18*F18)>F18,F18,(L18*F18)) -> 276 | N18: =M18/11.5 -> 24 | O18: =ROUNDUP(N18,0) -> 24 | P18: =O18*0.25 -> 6 | Q18: =P18*3 -> 18 | R18: =ROUNDUP(Q18,0) -> 18 | S18: ='Manpower Allocation'!$D$18 -> 25 | T18: =R18+S18 -> 43 | U18: =I18/V18 -> 2676.8293 | V18: 12 | W18: =(11*12*2)+(1*6*2) -> 276 | X18: =IF(J18>I18,V18,J18/U18) -> 12 | Y18: =ROUND(L18*W18,0) -> 435 | Z18: 0.5 | AA18: =Z18*X18 -> 6 | AB18: =ROUNDUP(AA18,0) -> 6 | AC18: =AB18*3 -> 18 | AD18: 1 M/C ~ 24 Spindles (Ends) = 1 Opt ~48 Spindles | AE18: =T18+T4 -> 66 | AF18: P1 | AG18: 1 | AH18: 6 | AJ18: =T18+T4 -> 66 | AT18: =J18/T18 -> 1177.062 | AU18: Operator | AV18: =Q30 -> 17.9375 | AW18: =6*3 -> 18 | AX18: For 24 Winders | AY18: =6*3 -> 18 | AZ18: =6*3 -> 18 | BA18: =6*3 -> 18 | BB18: =6*3 -> 18 | BC18: =6*3 -> 18 | BD18: =6*3 -> 18 | BE18: =6*3 -> 18 | BF18: =6*3 -> 18 | BG18: =4*3 -> 12 | BH18: =6*3 -> 18 | BI18: =6*3 -> 18 | BJ18: =6*3 -> 18
A19: 1. POY | B19: 1. POY | C19: 46143 | D19: ='YN01'!$J$51 -> 2967.7287 | E19: ='YN01'!$B$51 -> 270.46771 | F19: =24*12-12 -> 276 | G19: ='YN01'!$H$43 -> 0.93424658 | H19: ='YN01'!$I$43 -> 0.97 | I19: =D19*E19*F19*G19*H19*0.00016 -> 32121.952 | J19: =(BP!F90+BP!F91)/DAY(EOMONTH(C19,0)) -> 40984.507 | L19: =J19/I19 -> 1.2759034 | M19: =IF((L19*F19)>F19,F19,(L19*F19)) -> 276 | N19: =M19/11.5 -> 24 | O19: =ROUNDUP(N19,0) -> 24 | P19: =O19*0.25 -> 6 | Q19: =P19*3 -> 18 | R19: =ROUNDUP(Q19,0) -> 18 | S19: ='Manpower Allocation'!$D$18 -> 25 | T19: =R19+S19 -> 43 | U19: =I19/V19 -> 2676.8293 | V19: 12 | W19: =(11*12*2)+(1*6*2) -> 276 | X19: =IF(J19>I19,V19,J19/U19) -> 12 | Y19: =ROUND(L19*W19,0) -> 352 | Z19: 0.5 | AA19: =Z19*X19 -> 6 | AB19: =ROUNDUP(AA19,0) -> 6 | AC19: =AB19*3 -> 18 | AE19: =T19+T5 -> 68 | AF19: P2 | AG19: 1 | AH19: 6 | AJ19: =T19+T5 -> 68 | AU19: Chips Charging | AV19: 3 | AW19: 3 | AY19: 3 | AZ19: 3 | BA19: 3 | BB19: 3 | BC19: 3 | BD19: 3 | BE19: 3 | BF19: 3 | BG19: 3 | BH19: 3 | BI19: 3 | BJ19: 3
A20: 1. POY | B20: 1. POY | C20: 46174 | D20: ='YN01'!$J$51 -> 2967.7287 | E20: ='YN01'!$B$51 -> 270.46771 | F20: =24*12-12 -> 276 | G20: ='YN01'!$H$43 -> 0.93424658 | H20: ='YN01'!$I$43 -> 0.97 | I20: =D20*E20*F20*G20*H20*0.00016 -> 32121.952 | J20: =(BP!G90+BP!G91)/DAY(EOMONTH(C20,0)) -> 35678.92 | L20: =J20/I20 -> 1.1107333 | M20: =IF((L20*F20)>F20,F20,(L20*F20)) -> 276 | N20: =M20/11.5 -> 24 | O20: =ROUNDUP(N20,0) -> 24 | P20: =O20*0.25 -> 6 | Q20: =P20*3 -> 18 | R20: =ROUNDUP(Q20,0) -> 18 | S20: ='Manpower Allocation'!$D$18 -> 25 | T20: =R20+S20 -> 43 | U20: =I20/V20 -> 2676.8293 | V20: 12 | W20: =(11*12*2)+(1*6*2) -> 276 | X20: =IF(J20>I20,V20,J20/U20) -> 12 | Y20: =ROUND(L20*W20,0) -> 307 | Z20: 0.5 | AA20: =Z20*X20 -> 6 | AB20: =ROUNDUP(AA20,0) -> 6 | AC20: =AB20*3 -> 18 | AE20: =T20+T6 -> 66 | AF20: P3 | AG20: 1 | AH20: 12 | AJ20: =T20+T6 -> 66 | AU20: Dryer | AV20: 6 | AW20: 3 | AX20: ** 2 persons (one person on each floor) continuously monitor the utility part on every mc. & the level of infeed material in every vessels. And if there is any uncertainity found, they inform their supervisor @ it and ask them to do the corrections. This can be covered in EMS, with One or No person required to seperately monitor and update the readings. | AY20: 3 | AZ20: 3 | BA20: 3 | BB20: 3 | BC20: 3 | BD20: 3 | BE20: 3 | BF20: 3 | BG20: 3 | BH20: 3 | BI20: 3 | BJ20: 3
A21: 1. POY | B21: 1. POY | C21: 46204 | D21: ='YN01'!$J$51 -> 2967.7287 | E21: ='YN01'!$B$51 -> 270.46771 | F21: =24*12-12 -> 276 | G21: ='YN01'!$H$43 -> 0.93424658 | H21: ='YN01'!$I$43 -> 0.97 | I21: =D21*E21*F21*G21*H21*0.00016 -> 32121.952 | J21: =(BP!H90+BP!H91)/DAY(EOMONTH(C21,0)) -> 48507.406 | L21: =J21/I21 -> 1.5101014 | M21: =IF((L21*F21)>F21,F21,(L21*F21)) -> 276 | N21: =M21/11.5 -> 24 | O21: =ROUNDUP(N21,0) -> 24 | P21: =O21*0.25 -> 6 | Q21: =P21*3 -> 18 | R21: =ROUNDUP(Q21,0) -> 18 | S21: ='Manpower Allocation'!$D$18 -> 25 | T21: =R21+S21 -> 43 | U21: =I21/V21 -> 2676.8293 | V21: 12 | W21: =(11*12*2)+(1*6*2) -> 276 | X21: =IF(J21>I21,V21,J21/U21) -> 12 | Y21: =ROUND(L21*W21,0) -> 417 | Z21: 0.5 | AA21: =Z21*X21 -> 6 | AB21: =ROUNDUP(AA21,0) -> 6 | AC21: =AB21*3 -> 18 | AE21: =T21+T7 -> 66 | AF21: P4 | AG21: 1 | AH21: 12 | AJ21: =T21+T7 -> 66 | AU21: Spinning + Control Room | AV21: 9 | AW21: =(2*3)+(1*2) -> 8 | AY21: =(2*3)+(1*2) -> 8 | AZ21: =(2*3)+(1*2) -> 8 | BA21: =(2*3)+(1*2) -> 8 | BB21: =(2*3)+(1*2) -> 8 | BC21: =(2*3)+(1*2) -> 8 | BD21: =(2*3)+(1*2) -> 8 | BE21: =(2*3)+(1*2) -> 8 | BF21: =(2*3)+(1*2) -> 8 | ... BJ21: =(2*3)+(1*2) -> 8
A22: 1. POY | B22: 1. POY | C22: 46235 | D22: ='YN01'!$J$51 -> 2967.7287 | E22: ='YN01'!$B$51 -> 270.46771 | F22: =24*12-12 -> 276 | G22: ='YN01'!$H$43 -> 0.93424658 | H22: ='YN01'!$I$43 -> 0.97 | I22: =D22*E22*F22*G22*H22*0.00016 -> 32121.952 | J22: =(BP!I90+BP!I91)/DAY(EOMONTH(C22,0)) -> 37814.245 | L22: =J22/I22 -> 1.1772088 | M22: =IF((L22*F22)>F22,F22,(L22*F22)) -> 276 | N22: =M22/11.5 -> 24 | O22: =ROUNDUP(N22,0) -> 24 | P22: =O22*0.25 -> 6 | Q22: =P22*3 -> 18 | R22: =ROUNDUP(Q22,0) -> 18 | S22: ='Manpower Allocation'!$D$18 -> 25 | T22: =R22+S22 -> 43 | U22: =I22/V22 -> 2676.8293 | V22: 12 | W22: =(11*12*2)+(1*6*2) -> 276 | X22: =IF(J22>I22,V22,J22/U22) -> 12 | Y22: =ROUND(L22*W22,0) -> 325 | Z22: 0.5 | AA22: =Z22*X22 -> 6 | AB22: =ROUNDUP(AA22,0) -> 6 | AC22: =AB22*3 -> 18 | AE22: =T22+T8 -> 68 | AF22: P5 | AG22: 1 | AH22: 12 | AJ22: =T22+T8 -> 68 | AU22: Data Entry | AV22: 1 | AW22: 1 | AX22: ** DEO can be asked to sit in Control Room to monitor the Spinning parameters while he does the DE's. Also, his current workload should be minimized through Digitization. | AY22: 1 | AZ22: 1 | BA22: 1 | BB22: 1 | BC22: 1 | BD22: 1 | BE22: 1 | BF22: 1 | BG22: 1 | BH22: 1 | BI22: 1 | BJ22: 1
A23: 1. POY | B23: 1. POY | C23: 46266 | D23: ='YN01'!$J$51 -> 2967.7287 | E23: ='YN01'!$B$51 -> 270.46771 | F23: =24*12-12 -> 276 | G23: ='YN01'!$H$43 -> 0.93424658 | H23: ='YN01'!$I$43 -> 0.97 | I23: =D23*E23*F23*G23*H23*0.00016 -> 32121.952 | J23: =(BP!J90+BP!J91)/DAY(EOMONTH(C23,0)) -> 35651.419 | L23: =J23/I23 -> 1.1098771 | M23: =IF((L23*F23)>F23,F23,(L23*F23)) -> 276 | N23: =M23/11.5 -> 24 | O23: =ROUNDUP(N23,0) -> 24 | P23: =O23*0.25 -> 6 | Q23: =P23*3 -> 18 | R23: =ROUNDUP(Q23,0) -> 18 | S23: ='Manpower Allocation'!$D$18 -> 25 | T23: =R23+S23 -> 43 | U23: =I23/V23 -> 2676.8293 | V23: 12 | W23: =(11*12*2)+(1*6*2) -> 276 | X23: =IF(J23>I23,V23,J23/U23) -> 12 | Y23: =ROUND(L23*W23,0) -> 306 | Z23: 0.5 | AA23: =Z23*X23 -> 6 | AB23: =ROUNDUP(AA23,0) -> 6 | AC23: =AB23*3 -> 18 | AE23: =T23+T9 -> 72 | AF23: P6 | AG23: 1 | AH23: 12 | AJ23: =T23+T9 -> 72 | AU23: Burn Out | AV23: 6 | AW23: 6 | AY23: 6 | AZ23: 6 | BA23: 6 | BB23: 6 | BC23: 6 | BD23: 6 | BE23: 6 | BF23: 6 | BG23: 6 | BH23: 6 | BI23: 6 | BJ23: 6
A24: 1. POY | B24: 1. POY | C24: 46296 | D24: ='YN01'!$J$51 -> 2967.7287 | E24: ='YN01'!$B$51 -> 270.46771 | F24: =24*12-12 -> 276 | G24: ='YN01'!$H$43 -> 0.93424658 | H24: ='YN01'!$I$43 -> 0.97 | I24: =D24*E24*F24*G24*H24*0.00016 -> 32121.952 | J24: =(BP!K90+BP!K91)/DAY(EOMONTH(C24,0)) -> 37403.159 | L24: =J24/I24 -> 1.1644111 | M24: =IF((L24*F24)>F24,F24,(L24*F24)) -> 276 | N24: =M24/11.5 -> 24 | O24: =ROUNDUP(N24,0) -> 24 | P24: =O24*0.25 -> 6 | Q24: =P24*3 -> 18 | R24: =ROUNDUP(Q24,0) -> 18 | S24: ='Manpower Allocation'!$D$18 -> 25 | T24: =R24+S24 -> 43 | U24: =I24/V24 -> 2676.8293 | V24: 12 | W24: =(11*12*2)+(1*6*2) -> 276 | X24: =IF(J24>I24,V24,J24/U24) -> 12 | Y24: =ROUND(L24*W24,0) -> 321 | Z24: 0.5 | AA24: =Z24*X24 -> 6 | AB24: =ROUNDUP(AA24,0) -> 6 | AC24: =AB24*3 -> 18 | AE24: =T24+T10 -> 69 | AF24: P7 | AG24: 2 | AH24: =AG24*12 -> 24 | AJ24: =T24+T10 -> 69 | AU24: PD Sample (M/C will install after 5 Month) | AV24: 3 | AW24: 3 | AY24: 3 | AZ24: 3 | BA24: 3 | BB24: 3 | BC24: 3 | BD24: 3 | BE24: 3 | BF24: 3 | BG24: 3 | BH24: 3 | BI24: 3 | BJ24: 3
A25: 1. POY | B25: 1. POY | C25: 46327 | D25: ='YN01'!$J$51 -> 2967.7287 | E25: ='YN01'!$B$51 -> 270.46771 | F25: =24*12-12 -> 276 | G25: ='YN01'!$H$43 -> 0.93424658 | H25: ='YN01'!$I$43 -> 0.97 | I25: =D25*E25*F25*G25*H25*0.00016 -> 32121.952 | J25: =(BP!L90+BP!L91)/DAY(EOMONTH(C25,0)) -> 34395.261 | L25: =J25/I25 -> 1.0707712 | M25: =IF((L25*F25)>F25,F25,(L25*F25)) -> 276 | N25: =M25/11.5 -> 24 | O25: =ROUNDUP(N25,0) -> 24 | P25: =O25*0.25 -> 6 | Q25: =P25*3 -> 18 | R25: =ROUNDUP(Q25,0) -> 18 | S25: ='Manpower Allocation'!$D$18 -> 25 | T25: =R25+S25 -> 43 | U25: =I25/V25 -> 2676.8293 | V25: 12 | W25: =(11*12*2)+(1*6*2) -> 276 | X25: =IF(J25>I25,V25,J25/U25) -> 12 | Y25: =ROUND(L25*W25,0) -> 296 | Z25: 0.5 | AA25: =Z25*X25 -> 6 | AB25: =ROUNDUP(AA25,0) -> 6 | AC25: =AB25*3 -> 18 | AE25: =T25+T11 -> 72 | AF25: P8 | AG25: 2 | AH25: =AG25*12 -> 24 | AJ25: =T25+T11 -> 72 | AU25: TOTAL | AV25: =SUM(AV18:AV24) -> 45.9375 | AW25: =SUM(AW18:AW24) -> 42 | AY25: =SUM(AY18:AY24) -> 42 | AZ25: =SUM(AZ18:AZ24) -> 42 | BA25: =SUM(BA18:BA24) -> 42 | BB25: =SUM(BB18:BB24) -> 42 | BC25: =SUM(BC18:BC24) -> 42 | BD25: =SUM(BD18:BD24) -> 42 | BE25: =SUM(BE18:BE24) -> 42 | BF25: =SUM(BF18:BF24) -> 42 | ... BJ25: =SUM(BJ18:BJ24) -> 42
