Workbook

Sheet WTT
A1: Location | B1: Business | C1: Section | D1: Sr_No | E1: Dept_Machine_Name | F1: Designation | G1: Machine_Count | H1: Workload | I1: Formulas | J1: HO_Scientific_Manpower | K1: Operator_Type | L1: Contractors | M1: Company_Associate | N1: HO_Final_Manpower | O1: General_Shift | P1: Shift_A | Q1: Shift_B | R1: Shift_C | S1: Reliever | T1: Remarks
A2: Vapi | B2: WTT | C2: Weaving Preparatory | D2: 1 | E2: Direct Warping | F2: Warper | G2: 4 | H2: 1 Machine / Warper | I2: 4*3 | J2: 12 | N2: 12 | O2: 0 | P2: 4 | Q2: 4 | R2: 4 | S2: 0
A3: Vapi | B3: WTT | C3: Weaving Preparatory | D3: 2 | E3: Direct Warping | F3: Creel Boy | G3: 4 | H3: 1 Machine / Creel Boy | I3: 4*3 | J3: 12 | N3: 12 | O3: 0 | P3: 4 | Q3: 4 | R3: 4 | S3: 0
A4: Vapi | B4: WTT | C4: Weaving Preparatory | D4: 3 | E4: Section Warping | F4: Warper | G4: 5 | H4: 1 Machine / Warper | I4: 5*3 | J4: 15 | N4: 15 | O4: 0 | P4: 5 | Q4: 5 | R4: 5 | S4: 0
A5: Vapi | B5: WTT | C5: Weaving Preparatory | D5: 4 | E5: Section Warping | F5: Creel Boy | G5: 5 | H5: 1 Machine / Creel Boy | I5: 5*3 | J5: 15 | N5: 15 | O5: 0 | P5: 5 | Q5: 5 | R5: 5 | S5: 0
A6: Vapi | B6: WTT | C6: Weaving Preparatory | D6: 5 | E6: Sizing | F6: Sizer | G6: 4 | H6: 1 Machine / Operator | I6: 4*3 | J6: 12 | N6: 12 | O6: 0 | P6: 4 | Q6: 4 | R6: 4 | S6: 0
A7: Vapi | B7: WTT | C7: Weaving Preparatory | D7: 6 | E7: Sizing | F7: Back Sizer | G7: 4 | H7: 1 Machine / Back Sizer | I7: 4*3 | J7: 12 | N7: 12 | O7: 0 | P7: 4 | Q7: 4 | R7: 4 | S7: 0
A8: Vapi | B8: WTT | C8: Weaving Preparatory | D8: 7 | E8: Sizing | F8: Mixing Man | H8: 1 Operator / Shift | I8: 1*3 | J8: 3 | N8: 3 | O8: 0 | P8: 1 | Q8: 1 | R8: 1 | S8: 0
A9: Vapi | B9: WTT | C9: Weaving Preparatory | D9: 8 | E9: Winding (30 Drum) | F9: Winding Opt | G9: 1 | H9: 13 Drum / Operator (50 Drums) | I9: (50/13)*3 | J9: =ROUNDUP(11.53846154,0) -> 12 | N9: 12 | O9: 0 | P9: 4 | Q9: 4 | R9: 4 | S9: 0 | T9: Req. 11.53, given 12
A10: Vapi | B10: WTT | C10: Weaving Preparatory | D10: 9 | E10: Sample Winding | F10: Winding Opt | G10: 1 | H10: 1 Operator / Shift | I10: 1*3 | J10: 3 | N10: 3 | O10: 0 | P10: 1 | Q10: 1 | R10: 1 | S10: 0
A11: Vapi | B11: WTT | C11: Weaving Preparatory | D11: 10 | E11: Winding (30 Drum) | F11: Beam Carrier | H11: 03 Operator / Shift | I11: 3*3 | J11: 9 | N11: 9 | O11: 0 | P11: 3 | Q11: 3 | R11: 3 | S11: 0
A12: Vapi | B12: WTT | C12: Weaving Preparatory | D12: 11 | E12: Winding (30 Drum) | F12: Preventive Fitter | H12: 06 Fitter in General Shift | I12: 6*1 | J12: 6 | N12: 6 | O12: 6 | P12: 0 | Q12: 0 | R12: 0 | S12: 0
A13: Vapi | B13: WTT | C13: Weaving Preparatory | D13: 12 | E13: Winding (30 Drum) | F13: Shift Fitter | H13: 01 Fitter / Shift | I13: 1*3 | J13: 3 | N13: 3 | O13: 0 | P13: 1 | Q13: 1 | R13: 1 | S13: 0
A14: Vapi | B14: WTT | C14: Weaving Preparatory | D14: 13 | E14: Winding (30 Drum) | F14: MIS Coordinator | H14: 1 Operator / Shift | I14: 1*3 | J14: 3 | N14: 3 | O14: 0 | P14: 1 | Q14: 1 | R14: 1 | S14: 0
A15: Vapi | B15: WTT | C15: Weaving Preparatory | D15: 14 | E15: Winding (30 Drum) | F15: Housekeeping | H15: 1 Operator / Shift | I15: 1*3 | J15: 3 | N15: 3 | O15: 0 | P15: 1 | Q15: 1 | R15: 1 | S15: 0
A16: Vapi | B16: WTT | C16: Weaving Preparatory | D16: 15 | E16: New Sample Section Warping | F16: Warper | G16: 1 | H16: 1 Operator / Shift | I16: 1*3 | J16: 3 | N16: 3 | O16: 0 | P16: 1 | Q16: 1 | R16: 1 | S16: 0
A17: Vapi | B17: WTT | C17: Weaving Preparatory | D17: 16 | E17: New Sample Section Warping | F17: Creel Boy | H17: 1 Machine / Creel Boy | I17: 1*3 | J17: 3 | N17: 3 | O17: 0 | P17: 1 | Q17: 1 | R17: 1 | S17: 0
A18: Vapi | B18: WTT | C18: Weaving Preparatory | D18: 17 | E18: New Sample Section Warping | F18: Creel Boy (Material Handler) | H18: 1 Machine / Creel Boy | I18: 1*1 | J18: 1 | N18: 1 | O18: 0 | P18: 1 | Q18: 0 | R18: 0 | S18: 0
A19: Vapi | B19: WTT | C19: Loom Shed | D19: 1 | E19: Dobby&Jaquard | F19: Weaver | G19: 181 | H19: 6 Looms / Operator | I19: (181/6)*3 | J19: 90.5 | K19: Direct | N19: ='Weaving Back-Up'!F6 -> 93 | O19: 0 | P19: 31 | Q19: 31 | R19: 31 | S19: 0
A20: Vapi | B20: WTT | C20: Loom Shed | D20: 2 | E20: Dobby&Jaquard | F20: Weaver - Lunch Reliver | H20: 5 Weavers / Reliever | I20: (93/5) | J20: 18.6 | K20: Indirect | N20: ='Weaving Back-Up'!F10+3 -> 27 | O20: 0 | P20: 9 | Q20: 9 | R20: 9 | S20: 0
A21: Vapi | B21: WTT | C21: Loom Shed | D21: 3 | E21: Dobby&Jaquard | F21: Knotter | H21: 135 Knotting/Day (5Kn/Op) | I21: (45/5)*3 | J21: 27 | K21: Indirect | N21: 30 | O21: 0 | P21: 10 | Q21: 10 | R21: 10 | S21: 0 | T21: Req. 27, given 30
A22: Vapi | B22: WTT | C22: Loom Shed | D22: 4 | E22: Dobby&Jaquard | F22: Beam Loader | H22: 34 Machine / Operator | I22: (181/34)*3 | J22: 15.97 | K22: Direct | N22: 15 | O22: 0 | P22: 5 | Q22: 5 | R22: 5 | S22: 0
A23: Vapi | B23: WTT | C23: Loom Shed | D23: 5 | E23: Dobby&Jaquard | F23: Weft Boy | H23: 45 Machine / Operator | I23: (181/45)*3 | J23: 12.07 | K23: Direct | N23: 12 | O23: 0 | P23: 4 | Q23: 4 | R23: 4 | S23: 0
A24: Vapi | B24: WTT | C24: Loom Shed | D24: 6 | E24: Dobby&Jaquard | F24: Roll Doffer | H24: 42 Machine / Operator | I24: (181/42)*3 | J24: 12.93 | K24: Direct | N24: 16 | O24: 1 | P24: 5 | Q24: 5 | R24: 5 | S24: 0
A25: Vapi | B25: WTT | C25: Loom Shed | D25: 7 | E25: Dobby&Jaquard | F25: Dobby & Jacquard - Pile Ratio Checker | H25: 2 Operator / Shift | I25: 2*3 | J25: 6 | K25: Indirect | N25: 6 | O25: 0 | P25: 2 | Q25: 2 | R25: 2 | S25: 0
A26: Vapi | B26: WTT | C26: Loom Shed | D26: 8 | E26: Dobby&Jaquard | F26: Dobby & Jacquard - Quality Checker | H26: 1 Operator / Shift | I26: 1*3 | J26: 3 | K26: Indirect | N26: 3 | O26: 0 | P26: 1 | Q26: 1 | R26: 1 | S26: 0
A27: Vapi | B27: WTT | C27: Loom Shed | D27: 9 | E27: Dobby&Jaquard | F27: Data Opt | H27: 1 Operator / Shift | I27: 1*3 | J27: 3 | K27: Indirect | N27: 3 | O27: 0 | P27: 1 | Q27: 1 | R27: 1 | S27: 0
A28: Vapi | B28: WTT | C28: Loom Shed | D28: 10 | E28: Dobby&Jaquard | F28: Production Fitter | H28: 24 Machine / Operator | I28: (181/24)*3 | J28: 22.62 | K28: Direct | N28: ='Weaving Back-Up'!F11 -> 30 | O28: 0 | P28: 10 | Q28: 10 | R28: 10 | S28: 0
A29: Vapi | B29: WTT | C29: Loom Shed | D29: 11 | E29: Dobby&Jaquard | F29: PM-Fitter | H29: Fitter in General Shift | I29: 6+6+5 | J29: 17 | K29: Indirect | N29: 17 | O29: 0 | P29: 6 | Q29: 6 | R29: 5 | S29: 0
A30: Vapi | B30: WTT | C30: Loom Shed | D30: 12 | E30: Dobby&Jaquard | F30: PM-Fitter | H30: 1 Fitter / Shift | I30: 1*3 | J30: 3 | K30: Indirect | N30: 3 | O30: 0 | P30: 1 | Q30: 1 | R30: 1 | S30: 0
A31: Vapi | B31: WTT | C31: Loom Shed | D31: 13 | E31: Dobby&Jaquard | F31: Drawer | H31: 28 Machine / Operator | I31: (181/28)*3 | J31: 19.39 | K31: Direct | N31: 21 | O31: 0 | P31: 7 | Q31: 7 | R31: 7 | S31: 0
A32: Vapi | B32: WTT | C32: Loom Shed | D32: 14 | E32: Dobby&Jaquard | F32: Quality Checker / Mender | H32: 2 Machines | I32: 3*3 | J32: 9 | K32: Indirect | N32: 9 | O32: 0 | P32: 3 | Q32: 3 | R32: 3 | S32: 0
A33: Vapi | B33: WTT | C33: Loom Shed | D33: 15 | E33: Dobby&Jaquard | F33: Housekeeping | H33: 1 Operator / Shift | I33: 1*3 | J33: 3 | K33: Indirect | N33: 3 | O33: 0 | P33: 1 | Q33: 1 | R33: 1 | S33: 0
A34: Vapi | B34: WTT | C34: Grey Folding | D34: 1 | F34: Rope Maker | G34: 7 | H34: 1 Machine / Operator | I34: 7*3 | J34: 21 | K34: Direct | N34: 21 | O34: 0 | P34: 7 | Q34: 7 | R34: 7 | S34: 0
A35: Vapi | B35: WTT | C35: Grey Folding | D35: 2 | F35: Rope Stitcher | G35: 7 | H35: 1 Machine / Operator | I35: 7*3 | J35: 21 | K35: Direct | N35: 21 | O35: 0 | P35: 7 | Q35: 7 | R35: 7 | S35: 0
A36: Vapi | B36: WTT | C36: Grey Folding | D36: 3 | F36: Crane Handling | G36: 2 | H36: 1 Crane / Operator | I36: 1*3 | J36: 3 | K36: Direct | N36: 3 | O36: 0 | P36: 1 | Q36: 1 | R36: 1 | S36: 0
A37: Vapi | B37: WTT | C37: Grey Folding | D37: 4 | F37: Inspection Machine | G37: 1 | H37: 1 Machine / Operator | I37: 1*3 | J37: 3 | K37: Direct | N37: 3 | O37: 0 | P37: 1 | Q37: 1 | R37: 1 | S37: 0
A38: Vapi | B38: WTT | C38: Grey Folding | D38: 5 | F38: Material Handler | H38: 3 Handler / Shift | I38: 3*3 | J38: 9 | K38: Indirect | N38: 9 | O38: 0 | P38: 3 | Q38: 3 | R38: 3 | S38: 0
A39: Vapi | B39: WTT | C39: Grey Folding | D39: 6 | F39: Driver | G39: 1 | H39: 1 Machine / Operator | I39: 1*3 | J39: 3 | K39: Direct | N39: 3 | O39: 0 | P39: 1 | Q39: 1 | R39: 1 | S39: 0
A40: Vapi | B40: WTT | C40: Grey Folding | D40: 7 | F40: MIS & Floor Coordinator | H40: 1 Operator / Shift | I40: 1*3 | J40: 3 | K40: Indirect | N40: 3 | O40: 0 | P40: 1 | Q40: 1 | R40: 1 | S40: 0
...

Sheet Weaving Back-Up
A1: Details | B1: Dobby_unit1 | C1: Dobby_unit2 | D1: Jacquard_1 | E1: Jacquard_2 | F1: TOTAL
A2: Looms Distribution (Unitwise) | B2: 51 | C2: 90 | D2: 36 | E2: 4 | F2: =SUM(B2:E2) -> 181
A3: Looms/Weaver | B3: 6 | C3: 6 | D3: 6 | E3: 4
B4: =B2/B3 -> 8.5 | C4: =C2/C3 -> 15 | D4: =D2/D3 -> 6 | E4: =E2/E3 -> 1
A5: Weavers/shift | B5: =ROUND(B4,0) -> 9 | C5: 15 | D5: =D4 -> 6 | E5: 1
A6: Weaver/ Day | B6: =B5*3 -> 27 | C6: =C5*3 -> 45 | D6: =D5*3 -> 18 | E6: =E5*3 -> 3 | F6: =SUM(B6:E6) -> 93
A8: Weavers Per Reliever (No.) | B8: 5 | C8: 5 | D8: 5 | E8: 5 | F8: =SUM(B8:E8) -> 20
A9: Relievers/ Shift | B9: =ROUND((B5/B8),0.25) -> 2 | C9: =ROUND((C5/C8),0) -> 3 | D9: =ROUNDUP((D5/D8),0) -> 2 | E9: =ROUNDUP((E5/E8),0.25) -> 1 | F9: =SUM(B9:E9) -> 8
A10: Relievers/ Day | B10: =B9*3 -> 6 | C10: =C9*3 -> 9 | D10: =D9*3 -> 6 | E10: =E9*3 -> 3 | F10: =SUM(B10:E10) -> 24
A11: Production Fitter | B11: =ROUNDUP(B2/24,0)*3 -> 9 | C11: =ROUNDUP(C2/24,0)*3 -> 12 | D11: =ROUNDUP(D2/24,0)*3 -> 6 | E11: =ROUNDUP(E2/24,0)*3 -> 3 | F11: =SUM(B11:E11) -> 30
A12: Drawer | B12: =ROUNDUP(B2/28,0)*3 -> 6 | C12: =ROUNDUP(C2/28,0)*3 -> 12 | D12: =ROUNDUP(D2/28,0)*3 -> 6 | E12: =ROUNDUP(E2/28,0)*3 -> 3 | F12: =SUM(B12:E12) -> 27

Sheet Stenter
A1: Dynamic Shift Planning Based on MT / Day
A3: Required Production / Day (MT) | B3: 85 | D3: Change only yellow input cells
A4: Capacity / Machine / Shift (MT) | B4: 7
A5: Available Machines | B5: 5
A6: Required Machine-Shifts / Day | B6: =ROUNDUP(B3/B4,0) -> 13
A7: Base Machines / Shift | B7: =ROUNDDOWN(B6/3,0) -> 4
A8: Remainder Machine-Shifts | B8: =MOD(B6,3) -> 1
A10: Shift | B10: Machines Planned | C10: Capacity / Machine / Shift | D10: Production (MT)
A11: 1st Shift | B11: =MIN($B$5,$B$7+IF(1<=$B$8,1,0)) -> 5 | C11: =$B$4 -> 7 | D11: =B11*C11 -> 35
A12: 2nd Shift | B12: =MIN($B$5,$B$7+IF(2<=$B$8,1,0)) -> 4 | C12: =$B$4 -> 7 | D12: =B12*C12 -> 28
A13: 3rd Shift | B13: =MIN($B$5,$B$7+IF(3<=$B$8,1,0)) -> 4 | C13: =$B$4 -> 7 | D13: =B13*C13 -> 28
A14: Total | B14: =SUM(B11:B13) -> 13 | D14: =SUM(D11:D13) -> 91
A17: Designation | B17: Workload | C17: Formula Logic | D17: HO_Scientific_Manpower | E17: HO_Final_Manpower | F17: General_Shift | G17: Shift_A | H17: Shift_B | I17: Shift_C | J17: Reliever
A18: Padder Operator | B18: 1 Machine / Operator | C18: =B11+B12+B13 -> 13 | D18: =D18 | E18: =E18 | F18: 0 | G18: =B11*1 -> 5 | H18: =B12*1 -> 4 | I18: =B13*1 -> 4 | J18: 0
A19: Biancalanni | B19: 2 Operator / Machine | C19: =(B11*2)+(B12*2)+(B13*2) -> 26 | D19: =D19 | E19: =E19 | F19: 0 | G19: =B11*2 -> 10 | H19: =B12*2 -> 8 | I19: =B13*2 -> 8 | J19: 0
A20: Stenter Operator | B20: 1 Machine / Operator | C20: =B11+B12+B13 -> 13 | D20: =D20 | E20: =E20 | F20: 0 | G20: =B11*1 -> 5 | H20: =B12*1 -> 4 | I20: =B13*1 -> 4 | J20: 0
A23: How it works
A24: 1. Required machine-shifts = Required MT / Capacity per Machine per Shift
A25: 2. Machine-shifts are distributed across 3 shifts as evenly as possible
A26: 3. Extra machine-shifts are assigned from 1st shift onward
A27: 4. Operator manpower is then derived from shift-wise machine allocation
